<?xml version="1.0" encoding="utf-8"?>
<!-- This URDF was automatically created by SolidWorks to URDF Exporter! Originally created by Stephen Brawner (brawner@gmail.com) 
     Commit Version:   Build Version: 1.5.7444.6699
     For more information, please see http://wiki.ros.org/sw_urdf_exporter -->
<robot
  name="toy_car2">
  <link
    name="base_link">
    <inertial>
      <origin
        xyz="-0.12763 -2.0391E-07 0.061739"
        rpy="0 0 0" />
      <mass
        value="1.4471" />
      <inertia
        ixx="0.0040435"
        ixy="4.375E-12"
        ixz="9.4984E-06"
        iyy="0.0020504"
        iyz="-9.2647E-12"
        izz="0.0056763" />
    </inertial>
    <visual>
      <origin
        xyz="0 0 0"
        rpy="0 0 0" />
      <geometry>
        <mesh
          filename="package://toy_car/meshes/base_link.STL" />
      </geometry>
      <material
        name="">
        <color
          rgba="1 1 1 1" />
      </material>
    </visual>
    <collision>
      <origin
        xyz="0 0 0"
        rpy="0 0 0" />
      <geometry>
        <mesh
          filename="package://toy_car/meshes/base_link.STL" />
      </geometry>
    </collision>
  </link>
  <link
    name="front_left">
    <inertial>
      <origin
        xyz="-2.4286E-17 0.015327 -0.0062129"
        rpy="0 0 0" />
      <mass
        value="0.021111" />
      <inertia
        ixx="2.4537E-06"
        ixy="-2.0655E-21"
        ixz="3.8606E-21"
        iyy="6.0813E-06"
        iyz="3.6609E-08"
        izz="6.0895E-06" />
    </inertial>
    <visual>
      <origin
        xyz="0 0 0"
        rpy="0 0 0" />
      <geometry>
        <mesh
          filename="package://toy_car/meshes/front_left.STL" />
      </geometry>
      <material
        name="">
        <color
          rgba="0.89804 0.91765 0.92941 1" />
      </material>
    </visual>
    <collision>
      <origin
        xyz="0 0 0"
        rpy="0 0 0" />
      <geometry>
        <mesh
          filename="package://toy_car/meshes/front_left.STL" />
      </geometry>
    </collision>
  </link>
  <joint
    name="front_left_joint"
    type="fixed">
    <origin
      xyz="-0.021 0.125 0.115"
      rpy="0 0 0" />
    <parent
      link="base_link" />
    <child
      link="front_left" />
    <axis
      xyz="0 0 0" />
  </joint>
  <link
    name="front_left_suspension">
    <inertial>
      <origin
        xyz="1.4121E-05 0.0045607 -0.019589"
        rpy="0 0 0" />
      <mass
        value="0.10849" />
      <inertia
        ixx="2.5333E-05"
        ixy="-1.617E-08"
        ixz="-5.7763E-10"
        iyy="2.82E-05"
        iyz="-6.308E-07"
        izz="1.3787E-05" />
    </inertial>
    <visual>
      <origin
        xyz="0 0 0"
        rpy="0 0 0" />
      <geometry>
        <mesh
          filename="package://toy_car/meshes/front_left_suspension.STL" />
      </geometry>
      <material
        name="">
        <color
          rgba="0.89804 0.91765 0.92941 1" />
      </material>
    </visual>
    <collision>
      <origin
        xyz="0 0 0"
        rpy="0 0 0" />
      <geometry>
        <mesh
          filename="package://toy_car/meshes/front_left_suspension.STL" />
      </geometry>
    </collision>
  </link>
  <joint
    name="front_left_suspension_joint"
    type="prismatic">
    <origin
      xyz="0 0.027343 -0.07"
      rpy="0.17453 0 0" />
    <parent
      link="front_left" />
    <child
      link="front_left_suspension" />
    <axis
      xyz="0 0 -1" />
    <limit
      lower="-0.03"
      upper="0.03"
      effort="30"
      velocity="100" />
  </joint>
  <link
    name="front_left_wheel">
    <inertial>
      <origin
        xyz="-1.2143E-17 0.02 0"
        rpy="0 0 0" />
      <mass
        value="0.389" />
      <inertia
        ixx="0.00072452"
        ixy="-2.1344E-19"
        ixz="5.8729E-20"
        iyy="0.0013777"
        iyz="2.532E-18"
        izz="0.00072452" />
    </inertial>
    <visual>
      <origin
        xyz="0 0 0"
        rpy="0 0 0" />
      <geometry>
        <mesh
          filename="package://toy_car/meshes/front_left_wheel.STL" />
      </geometry>
      <material
        name="">
        <color
          rgba="1 1 1 1" />
      </material>
    </visual>
    <collision>
      <origin
        xyz="0 0 0"
        rpy="0 0 0" />
      <geometry>
        <mesh
          filename="package://toy_car/meshes/front_left_wheel.STL" />
      </geometry>
    </collision>
  </link>
  <joint
    name="front_left_wheel_joint"
    type="continuous">
    <origin
      xyz="1.1246E-05 0.031062 -0.064981"
      rpy="-0.17453 0 0" />
    <parent
      link="front_left_suspension" />
    <child
      link="front_left_wheel" />
    <axis
      xyz="0 1 0" />
    <limit
      effort="3.1"
      velocity="7" />
    <dynamics
      damping="0"
      friction="0" />
  </joint>
  <link
    name="front_right">
    <inertial>
      <origin
        xyz="-5.20417042793042E-18 -0.0153267239617477 -0.00621293030951707"
        rpy="0 0 0" />
      <mass
        value="0.0211105794692306" />
      <inertia
        ixx="2.45369235482973E-06"
        ixy="-1.27432044442246E-21"
        ixz="1.95963649236477E-21"
        iyy="6.08127961989932E-06"
        iyz="-3.66094605714801E-08"
        izz="6.08949128777743E-06" />
    </inertial>
    <visual>
      <origin
        xyz="0 0 0"
        rpy="0 0 0" />
      <geometry>
        <mesh
          filename="package://toy_car/meshes/front_right.STL" />
      </geometry>
      <material
        name="">
        <color
          rgba="0.792156862745098 0.819607843137255 0.933333333333333 1" />
      </material>
    </visual>
    <collision>
      <origin
        xyz="0 0 0"
        rpy="0 0 0" />
      <geometry>
        <mesh
          filename="package://toy_car/meshes/front_right.STL" />
      </geometry>
    </collision>
  </link>
  <joint
    name="front_right_joint"
    type="fixed">
    <origin
      xyz="-0.021 -0.125 0.115"
      rpy="0 0 0" />
    <parent
      link="base_link" />
    <child
      link="front_right" />
    <axis
      xyz="0 0 0" />
  </joint>
  <link
    name="front_right_suspension">
    <inertial>
      <origin
        xyz="1.4121E-05 -0.0045607 -0.019589"
        rpy="0 0 0" />
      <mass
        value="0.10849" />
      <inertia
        ixx="2.5333E-05"
        ixy="1.617E-08"
        ixz="-5.775E-10"
        iyy="2.82E-05"
        iyz="6.308E-07"
        izz="1.3787E-05" />
    </inertial>
    <visual>
      <origin
        xyz="0 0 0"
        rpy="0 0 0" />
      <geometry>
        <mesh
          filename="package://toy_car/meshes/front_right_suspension.STL" />
      </geometry>
      <material
        name="">
        <color
          rgba="0.79216 0.81961 0.93333 1" />
      </material>
    </visual>
    <collision>
      <origin
        xyz="0 0 0"
        rpy="0 0 0" />
      <geometry>
        <mesh
          filename="package://toy_car/meshes/front_right_suspension.STL" />
      </geometry>
    </collision>
  </link>
  <joint
    name="front_right_suspension_joint"
    type="prismatic">
    <origin
      xyz="0 -0.027343 -0.07"
      rpy="-0.17453 0 0" />
    <parent
      link="front_right" />
    <child
      link="front_right_suspension" />
    <axis
      xyz="0 0 -1" />
    <limit
      lower="-0.03"
      upper="0.03"
      effort="30"
      velocity="100" />
  </joint>
  <link
    name="front_right_wheel">
    <inertial>
      <origin
        xyz="6.9389E-18 -0.02 -6.9389E-17"
        rpy="0 0 0" />
      <mass
        value="0.389" />
      <inertia
        ixx="0.00072452"
        ixy="-2.1418E-19"
        ixz="5.2657E-21"
        iyy="0.0013777"
        iyz="2.5529E-18"
        izz="0.00072452" />
    </inertial>
    <visual>
      <origin
        xyz="0 0 0"
        rpy="0 0 0" />
      <geometry>
        <mesh
          filename="package://toy_car/meshes/front_right_wheel.STL" />
      </geometry>
      <material
        name="">
        <color
          rgba="0.79216 0.81961 0.93333 1" />
      </material>
    </visual>
    <collision>
      <origin
        xyz="0 0 0"
        rpy="0 0 0" />
      <geometry>
        <mesh
          filename="package://toy_car/meshes/front_right_wheel.STL" />
      </geometry>
    </collision>
  </link>
  <joint
    name="front_right_wheel_joint"
    type="continuous">
    <origin
      xyz="1.1246E-05 -0.031062 -0.064981"
      rpy="0.17453 0 0" />
    <parent
      link="front_right_suspension" />
    <child
      link="front_right_wheel" />
    <axis
      xyz="0 1 0" />
    <limit
      effort="3.1"
      velocity="7" />
    <dynamics
      damping="0"
      friction="0" />
  </joint>
  <link
    name="rear_left">
    <inertial>
      <origin
        xyz="0 5.5511E-17 -0.015373"
        rpy="0 0 0" />
      <mass
        value="0.0060039" />
      <inertia
        ixx="1.4401E-06"
        ixy="-6.2135E-23"
        ixz="-3.3863E-23"
        iyy="5.06E-07"
        iyz="-2.6249E-22"
        izz="1.5458E-06" />
    </inertial>
    <visual>
      <origin
        xyz="0 0 0"
        rpy="0 0 0" />
      <geometry>
        <mesh
          filename="package://toy_car/meshes/rear_left.STL" />
      </geometry>
      <material
        name="">
        <color
          rgba="1 1 1 1" />
      </material>
    </visual>
    <collision>
      <origin
        xyz="0 0 0"
        rpy="0 0 0" />
      <geometry>
        <mesh
          filename="package://toy_car/meshes/rear_left.STL" />
      </geometry>
    </collision>
  </link>
  <joint
    name="rear_left_joint"
    type="fixed">
    <origin
      xyz="-0.288495633593833 0.1025 0.0564000000000001"
      rpy="0 0 0" />
    <parent
      link="base_link" />
    <child
      link="rear_left" />
    <axis
      xyz="0 0 0" />
  </joint>
  <link
    name="rear_left_suspension">
    <inertial>
      <origin
        xyz="-5.5511E-17 5.5511E-17 -0.036734"
        rpy="0 0 0" />
      <mass
        value="0.091202" />
      <inertia
        ixx="5.3783E-05"
        ixy="3.6307E-21"
        ixz="-3.6993E-21"
        iyy="5.3549E-05"
        iyz="2.4736E-21"
        izz="5.509E-05" />
    </inertial>
    <visual>
      <origin
        xyz="0 0 0"
        rpy="0 0 0" />
      <geometry>
        <mesh
          filename="package://toy_car/meshes/rear_left_suspension.STL" />
      </geometry>
      <material
        name="">
        <color
          rgba="1 1 1 1" />
      </material>
    </visual>
    <collision>
      <origin
        xyz="0 0 0"
        rpy="0 0 0" />
      <geometry>
        <mesh
          filename="package://toy_car/meshes/rear_left_suspension.STL" />
      </geometry>
    </collision>
  </link>
  <joint
    name="rear_left_suspension_joint"
    type="prismatic">
    <origin
      xyz="0 0 -0.06"
      rpy="0 0 0" />
    <parent
      link="rear_left" />
    <child
      link="rear_left_suspension" />
    <axis
      xyz="0 0 -1" />
    <limit
      lower="-0.02"
      upper="0.02"
      effort="30"
      velocity="100" />
    <dynamics
      damping="0"
      friction="0" />
  </joint>
  <link
    name="rear_right">
    <inertial>
      <origin
        xyz="-5.5511E-17 1.7347E-18 -0.015373"
        rpy="0 0 0" />
      <mass
        value="0.0060039" />
      <inertia
        ixx="1.4401E-06"
        ixy="8.5882E-24"
        ixz="-1.8723E-22"
        iyy="5.06E-07"
        iyz="1.5808E-22"
        izz="1.5458E-06" />
    </inertial>
    <visual>
      <origin
        xyz="0 0 0"
        rpy="0 0 0" />
      <geometry>
        <mesh
          filename="package://toy_car/meshes/rear_right.STL" />
      </geometry>
      <material
        name="">
        <color
          rgba="0.79216 0.81961 0.93333 1" />
      </material>
    </visual>
    <collision>
      <origin
        xyz="0 0 0"
        rpy="0 0 0" />
      <geometry>
        <mesh
          filename="package://toy_car/meshes/rear_right.STL" />
      </geometry>
    </collision>
  </link>
  <joint
    name="rear_right_joint"
    type="fixed">
    <origin
      xyz="-0.2885 -0.1025 0.0564"
      rpy="0 0 0" />
    <parent
      link="base_link" />
    <child
      link="rear_right" />
    <axis
      xyz="0 0 0" />
  </joint>
  <link
    name="rear_right_suspension">
    <inertial>
      <origin
        xyz="-1.1102E-16 -1.2317E-16 -0.036734"
        rpy="0 0 0" />
      <mass
        value="0.091202" />
      <inertia
        ixx="5.3783E-05"
        ixy="-8.963E-22"
        ixz="-6.1098E-21"
        iyy="5.3549E-05"
        iyz="-1.0626E-20"
        izz="5.509E-05" />
    </inertial>
    <visual>
      <origin
        xyz="0 0 0"
        rpy="0 0 0" />
      <geometry>
        <mesh
          filename="package://toy_car/meshes/rear_right_suspension.STL" />
      </geometry>
      <material
        name="">
        <color
          rgba="0.79216 0.81961 0.93333 1" />
      </material>
    </visual>
    <collision>
      <origin
        xyz="0 0 0"
        rpy="0 0 0" />
      <geometry>
        <mesh
          filename="package://toy_car/meshes/rear_right_suspension.STL" />
      </geometry>
    </collision>
  </link>
  <joint
    name="rear_right_suspension_joint"
    type="prismatic">
    <origin
      xyz="0 0 -0.06"
      rpy="0 0 0" />
    <parent
      link="rear_right" />
    <child
      link="rear_right_suspension" />
    <axis
      xyz="0 0 -1" />
    <limit
      lower="-0.02"
      upper="0.02"
      effort="30"
      velocity="100" />
    <dynamics
      damping="0"
      friction="0" />
  </joint>
  <link
    name="camera_left">
    <inertial>
      <origin
        xyz="-0.012054 -2.2913E-06 0.0012904"
        rpy="0 0 0" />
      <mass
        value="0.061453" />
      <inertia
        ixx="2.3571E-05"
        ixy="-9.7412E-10"
        ixz="2.1763E-08"
        iyy="4.2947E-06"
        iyz="-7.4E-10"
        izz="2.2106E-05" />
    </inertial>
    <visual>
      <origin
        xyz="0 0 0"
        rpy="0 0 0" />
      <geometry>
        <mesh
          filename="package://toy_car/meshes/camera_left.STL" />
      </geometry>
      <material
        name="">
        <color
          rgba="0.79216 0.81961 0.93333 1" />
      </material>
    </visual>
    <collision>
      <origin
        xyz="0 0 0"
        rpy="0 0 0" />
      <geometry>
        <mesh
          filename="package://toy_car/meshes/camera_left.STL" />
      </geometry>
    </collision>
  </link>
  <joint
    name="camera_left_joint"
    type="fixed">
    <origin
      xyz="0.0245 0.125 0.11"
      rpy="0 0 0" />
    <parent
      link="base_link" />
    <child
      link="camera_left" />
    <axis
      xyz="0 0 0" />
  </joint>
  <link
    name="camera_link">
    <inertial>
      <origin
        xyz="-9.6468E-05 -4.2262E-09 -0.010763"
        rpy="0 0 0" />
      <mass
        value="0.056857" />
      <inertia
        ixx="6.2816E-06"
        ixy="-1.3747E-12"
        ixz="6.378E-07"
        iyy="9.672E-06"
        iyz="1.913E-12"
        izz="1.4883E-05" />
    </inertial>
    <visual>
      <origin
        xyz="0 0 0"
        rpy="0 0 0" />
      <geometry>
        <mesh
          filename="package://toy_car/meshes/camera_link.STL" />
      </geometry>
      <material
        name="">
        <color
          rgba="0.79216 0.81961 0.93333 1" />
      </material>
    </visual>
    <collision>
      <origin
        xyz="0 0 0"
        rpy="0 0 0" />
      <geometry>
        <mesh
          filename="package://toy_car/meshes/camera_link.STL" />
      </geometry>
    </collision>
  </link>
  <joint
    name="camera_link_joint"
    type="fixed">
    <origin
      xyz="0.027007 0 0.105"
      rpy="0 0 0" />
    <parent
      link="base_link" />
    <child
      link="camera_link" />
    <axis
      xyz="0 0 0" />
  </joint>
  <link
    name="camera_center">
    <inertial>
      <origin
        xyz="-0.012054 -2.2913E-06 0.0012904"
        rpy="0 0 0" />
      <mass
        value="0.061453" />
      <inertia
        ixx="2.3571E-05"
        ixy="-9.7405E-10"
        ixz="2.1763E-08"
        iyy="4.2947E-06"
        iyz="-7.3987E-10"
        izz="2.2106E-05" />
    </inertial>
    <visual>
      <origin
        xyz="0 0 0"
        rpy="0 0 0" />
      <geometry>
        <mesh
          filename="package://toy_car/meshes/camera_center.STL" />
      </geometry>
      <material
        name="">
        <color
          rgba="0.79216 0.81961 0.93333 1" />
      </material>
    </visual>
    <collision>
      <origin
        xyz="0 0 0"
        rpy="0 0 0" />
      <geometry>
        <mesh
          filename="package://toy_car/meshes/camera_center.STL" />
      </geometry>
    </collision>
  </link>
  <joint
    name="camera_center_joint"
    type="fixed">
    <origin
      xyz="0.0404208856688172 0 0.0046602540378443"
      rpy="0 0.523598775598297 0" />
    <parent
      link="camera_link" />
    <child
      link="camera_center" />
    <axis
      xyz="0 0 0" />
  </joint>
  <link
    name="camera_right">
    <inertial>
      <origin
        xyz="-0.012054 -2.2913E-06 0.0012904"
        rpy="0 0 0" />
      <mass
        value="0.061453" />
      <inertia
        ixx="2.3571E-05"
        ixy="-9.7412E-10"
        ixz="2.1763E-08"
        iyy="4.2947E-06"
        iyz="-7.4E-10"
        izz="2.2106E-05" />
    </inertial>
    <visual>
      <origin
        xyz="0 0 0"
        rpy="0 0 0" />
      <geometry>
        <mesh
          filename="package://toy_car/meshes/camera_right.STL" />
      </geometry>
      <material
        name="">
        <color
          rgba="0.79216 0.81961 0.93333 1" />
      </material>
    </visual>
    <collision>
      <origin
        xyz="0 0 0"
        rpy="0 0 0" />
      <geometry>
        <mesh
          filename="package://toy_car/meshes/camera_right.STL" />
      </geometry>
    </collision>
  </link>
  <joint
    name="camera_right_joint"
    type="fixed">
    <origin
      xyz="0.0245 -0.125 0.11"
      rpy="0 0 0" />
    <parent
      link="base_link" />
    <child
      link="camera_right" />
    <axis
      xyz="0 0 0" />
  </joint>
  <link
    name="lidar_top">
    <inertial>
      <origin
        xyz="-0.01205 0.00052764 -0.028765"
        rpy="0 0 0" />
      <mass
        value="0.2" />
      <inertia
        ixx="1.9581E-05"
        ixy="-1.0396E-07"
        ixz="4.2839E-07"
        iyy="2.4125E-05"
        iyz="-9.4098E-09"
        izz="4.1418E-05" />
    </inertial>
    <visual>
      <origin
        xyz="0 0 0"
        rpy="0 0 0" />
      <geometry>
        <mesh
          filename="package://toy_car/meshes/lidar_top.STL" />
      </geometry>
      <material
        name="">
        <color
          rgba="0.79216 0.81961 0.93333 1" />
      </material>
    </visual>
    <collision>
      <origin
        xyz="0 0 0"
        rpy="0 0 0" />
      <geometry>
        <mesh
          filename="package://toy_car/meshes/lidar_top.STL" />
      </geometry>
    </collision>
  </link>
  <joint
    name="lidar_top_joint"
    type="fixed">
    <origin
      xyz="-0.085232 0 0.177"
      rpy="0 0 0" />
    <parent
      link="base_link" />
    <child
      link="lidar_top" />
    <axis
      xyz="0 0 0" />
  </joint>
  <link
    name="imu">
    <inertial>
      <origin
        xyz="8.6736E-19 -1.3878E-17 -0.005"
        rpy="0 0 0" />
      <mass
        value="0.001" />
      <inertia
        ixx="1.6667E-08"
        ixy="2.2488E-24"
        ixz="5.5145E-25"
        iyy="1.6667E-08"
        iyz="-3.5332E-25"
        izz="1.6667E-08" />
    </inertial>
    <visual>
      <origin
        xyz="0 0 0"
        rpy="0 0 0" />
      <geometry>
        <mesh
          filename="package://toy_car/meshes/imu.STL" />
      </geometry>
      <material
        name="">
        <color
          rgba="0.79216 0.81961 0.93333 1" />
      </material>
    </visual>
    <collision>
      <origin
        xyz="0 0 0"
        rpy="0 0 0" />
      <geometry>
        <mesh
          filename="package://toy_car/meshes/imu.STL" />
      </geometry>
    </collision>
  </link>
  <joint
    name="imu_joint"
    type="fixed">
    <origin
      xyz="-0.00499999999999977 0 0.13499737041193"
      rpy="0 0 0" />
    <parent
      link="base_link" />
    <child
      link="imu" />
    <axis
      xyz="0 0 0" />
  </joint>
  <link
    name="holder">
    <inertial>
      <origin
        xyz="0.05984 -6.925E-15 -0.022122"
        rpy="0 0 0" />
      <mass
        value="1.4328" />
      <inertia
        ixx="0.010959"
        ixy="-6.9457E-19"
        ixz="-0.0022984"
        iyy="0.0093029"
        iyz="3.2932E-20"
        izz="0.018191" />
    </inertial>
    <visual>
      <origin
        xyz="0 0 0"
        rpy="0 0 0" />
      <geometry>
        <mesh
          filename="package://toy_car/meshes/holder.STL" />
      </geometry>
      <material
        name="">
        <color
          rgba="0.79216 0.81961 0.93333 1" />
      </material>
    </visual>
    <collision>
      <origin
        xyz="0 0 0"
        rpy="0 0 0" />
      <geometry>
        <mesh
          filename="package://toy_car/meshes/holder.STL" />
      </geometry>
    </collision>
  </link>
  <joint
    name="holder_joint"
    type="fixed">
    <origin
      xyz="0.0015 0 0.034999"
      rpy="0 0 0" />
    <parent
      link="base_link" />
    <child
      link="holder" />
    <axis
      xyz="0 0 0" />
  </joint>
  <link
    name="left_plate">
    <inertial>
      <origin
        xyz="-0.0005 5.5511E-17 -6.245E-17"
        rpy="0 0 0" />
      <mass
        value="0.001455" />
      <inertia
        ixx="4.7056E-07"
        ixy="1.0588E-23"
        ixz="-2.3161E-23"
        iyy="3.949E-07"
        iyz="3.1441E-23"
        izz="7.5904E-08" />
    </inertial>
    <visual>
      <origin
        xyz="0 0 0"
        rpy="0 0 0" />
      <geometry>
        <mesh
          filename="package://toy_car/meshes/left_plate.STL" />
      </geometry>
      <material
        name="">
        <color
          rgba="1 1 1 1" />
      </material>
    </visual>
    <collision>
      <origin
        xyz="0 0 0"
        rpy="0 0 0" />
      <geometry>
        <mesh
          filename="package://toy_car/meshes/left_plate.STL" />
      </geometry>
    </collision>
  </link>
  <joint
    name="left_plate_joint"
    type="fixed">
    <origin
      xyz="0.12963 0.0875 -0.02548"
      rpy="0 0.50284 0" />
    <parent
      link="holder" />
    <child
      link="left_plate" />
    <axis
      xyz="0 0 0" />
  </joint>
  <link
    name="right_plate">
    <inertial>
      <origin
        xyz="-0.0005 1.3878E-17 0"
        rpy="0 0 0" />
      <mass
        value="0.001455" />
      <inertia
        ixx="4.7056E-07"
        ixy="-9.8746E-24"
        ixz="2.9779E-23"
        iyy="3.949E-07"
        iyz="-1.5771E-22"
        izz="7.5904E-08" />
    </inertial>
    <visual>
      <origin
        xyz="0 0 0"
        rpy="0 0 0" />
      <geometry>
        <mesh
          filename="package://toy_car/meshes/right_plate.STL" />
      </geometry>
      <material
        name="">
        <color
          rgba="1 1 1 1" />
      </material>
    </visual>
    <collision>
      <origin
        xyz="0 0 0"
        rpy="0 0 0" />
      <geometry>
        <mesh
          filename="package://toy_car/meshes/right_plate.STL" />
      </geometry>
    </collision>
  </link>
  <joint
    name="right_plate_joint"
    type="fixed">
    <origin
      xyz="0.12963 -0.0875 -0.02548"
      rpy="0 0.50284 0" />
    <parent
      link="holder" />
    <child
      link="right_plate" />
    <axis
      xyz="0 0 0" />
  </joint>
  <link
    name="nuc">
    <inertial>
      <origin
        xyz="0.00042144 5.6786E-05 0.015867"
        rpy="0 0 0" />
      <mass
        value="0.39954" />
      <inertia
        ixx="0.00047302"
        ixy="-3.1704E-07"
        ixz="-4.7752E-07"
        iyy="0.00043203"
        iyz="1.8337E-07"
        izz="0.00083697" />
    </inertial>
    <visual>
      <origin
        xyz="0 0 0"
        rpy="0 0 0" />
      <geometry>
        <mesh
          filename="package://toy_car/meshes/nuc.STL" />
      </geometry>
      <material
        name="">
        <color
          rgba="0.79216 0.81961 0.93333 1" />
      </material>
    </visual>
    <collision>
      <origin
        xyz="0 0 0"
        rpy="0 0 0" />
      <geometry>
        <mesh
          filename="package://toy_car/meshes/nuc.STL" />
      </geometry>
    </collision>
  </link>
  <joint
    name="nuc_joint"
    type="fixed">
    <origin
      xyz="-0.073998 7.38E-05 0.0071"
      rpy="0 0 0" />
    <parent
      link="base_link" />
    <child
      link="nuc" />
    <axis
      xyz="0 0 0" />
  </joint>
  <link
    name="rio">
    <inertial>
      <origin
        xyz="-5.9245E-05 -0.00039133 0.011832"
        rpy="0 0 0" />
      <mass
        value="0.192" />
      <inertia
        ixx="0.0004265"
        ixy="1.3278E-06"
        ixz="-1.3394E-07"
        iyy="0.00018312"
        iyz="9.7824E-08"
        izz="0.00058403" />
    </inertial>
    <visual>
      <origin
        xyz="0 0 0"
        rpy="0 0 0" />
      <geometry>
        <mesh
          filename="package://toy_car/meshes/rio.STL" />
      </geometry>
      <material
        name="">
        <color
          rgba="0.14902 0.14902 0.14902 1" />
      </material>
    </visual>
    <collision>
      <origin
        xyz="0 0 0"
        rpy="0 0 0" />
      <geometry>
        <mesh
          filename="package://toy_car/meshes/rio.STL" />
      </geometry>
    </collision>
  </link>
  <joint
    name="rio_joint"
    type="fixed">
    <origin
      xyz="-0.062748 0 0.0391"
      rpy="0 0 0" />
    <parent
      link="base_link" />
    <child
      link="rio" />
    <axis
      xyz="0 0 0" />
  </joint>
  <link
    name="jetson">
    <inertial>
      <origin
        xyz="0.013425 -0.004013 0.015834"
        rpy="0 0 0" />
      <mass
        value="0.2" />
      <inertia
        ixx="0.00039935"
        ixy="2.9289E-07"
        ixz="1.1282E-08"
        iyy="0.00035768"
        iyz="-7.04E-09"
        izz="0.00074652" />
    </inertial>
    <visual>
      <origin
        xyz="0 0 0"
        rpy="0 0 0" />
      <geometry>
        <mesh
          filename="package://toy_car/meshes/jetson.STL" />
      </geometry>
      <material
        name="">
        <color
          rgba="0.79216 0.81961 0.93333 1" />
      </material>
    </visual>
    <collision>
      <origin
        xyz="0 0 0"
        rpy="0 0 0" />
      <geometry>
        <mesh
          filename="package://toy_car/meshes/jetson.STL" />
      </geometry>
    </collision>
  </link>
  <joint
    name="jetson_joint"
    type="fixed">
    <origin
      xyz="-0.1085 0 0.0671"
      rpy="0 0 0" />
    <parent
      link="base_link" />
    <child
      link="jetson" />
    <axis
      xyz="0 0 0" />
  </joint>
  <link
    name="dummy">
    <inertial>
      <origin
        xyz="0 0 0"
        rpy="0 0 0" />
      <mass
        value="0" />
      <inertia
        ixx="0"
        ixy="0"
        ixz="0"
        iyy="0"
        iyz="0"
        izz="0" />
    </inertial>
    <visual>
      <origin
        xyz="0 0 0"
        rpy="0 0 0" />
      <geometry>
        <mesh
          filename="package://toy_car/meshes/dummy.STL" />
      </geometry>
      <material
        name="">
        <color
          rgba="1 1 1 1" />
      </material>
    </visual>
    <collision>
      <origin
        xyz="0 0 0"
        rpy="0 0 0" />
      <geometry>
        <mesh
          filename="package://toy_car/meshes/dummy.STL" />
      </geometry>
    </collision>
  </link>
  <joint
    name="dummy_joint"
    type="fixed">
    <origin
      xyz="-0.005 0 0.135"
      rpy="0 0 0" />
    <parent
      link="base_link" />
    <child
      link="dummy" />
    <axis
      xyz="0 0 0" />
  </joint>



  <transmission name="tran_left_wheel">
    <type>transmission_interface/SimpleTransmission</type>
    <joint name="front_left_wheel_joint">
      <hardwareInterface>VelocityJointInterface</hardwareInterface>
    </joint>
    <actuator name="motor1">
      <hardwareInterface>VelocityJointInterface</hardwareInterface>
      <mechanicalReduction>1</mechanicalReduction>
    </actuator>
  </transmission>

  <transmission name="tran_right_wheel">
    <type>transmission_interface/SimpleTransmission</type>
    <joint name="front_right_wheel_joint">
      <hardwareInterface>VelocityJointInterface</hardwareInterface>
    </joint>
    <actuator name="motor2">
      <hardwareInterface>VelocityJointInterface</hardwareInterface>
      <mechanicalReduction>1</mechanicalReduction>
    </actuator>
  </transmission>

  <transmission name="tran_front_left_sus">
    <type>transmission_interface/SimpleTransmission</type>
    <joint name="front_left_suspension_joint">
      <hardwareInterface>hardware_interface/EffortJointInterface</hardwareInterface>
    </joint>
    <actuator name="motor_sus1">
      <hardwareInterface>hardware_interface/EffortJointInterface</hardwareInterface>
      <mechanicalReduction>1</mechanicalReduction>
    </actuator>
  </transmission>

  <transmission name="tran_front_right_sus">
    <type>transmission_interface/SimpleTransmission</type>
    <joint name="front_right_suspension_joint">
      <hardwareInterface>hardware_interface/EffortJointInterface</hardwareInterface>
    </joint>
    <actuator name="motor_sus2">
      <hardwareInterface>hardware_interface/EffortJointInterface</hardwareInterface>
      <mechanicalReduction>1</mechanicalReduction>
    </actuator>
  </transmission>

  <transmission name="tran_rear_left_sus">
    <type>transmission_interface/SimpleTransmission</type>
    <joint name="rear_left_suspension_joint">
      <hardwareInterface>hardware_interface/EffortJointInterface</hardwareInterface>
    </joint>
    <actuator name="motor_sus3">
      <hardwareInterface>hardware_interface/EffortJointInterface</hardwareInterface>
      <mechanicalReduction>1</mechanicalReduction>
    </actuator>
  </transmission>

  <transmission name="tran_rear_right_sus">
    <type>transmission_interface/SimpleTransmission</type>
    <joint name="rear_right_suspension_joint">
      <hardwareInterface>hardware_interface/EffortJointInterface</hardwareInterface>
    </joint>
    <actuator name="motor_sus4">
      <hardwareInterface>hardware_interface/EffortJointInterface</hardwareInterface>
      <mechanicalReduction>1</mechanicalReduction>
    </actuator>
  </transmission>

  <gazebo reference="left_plate">
    <mu1>0.0001</mu1>
    <mu2>0.0001</mu2>
  </gazebo>

  <gazebo reference="right_plate">
    <mu1>0.0001</mu1>
    <mu2>0.0001</mu2>
  </gazebo>

  <gazebo reference="rear_right_suspension">
    <mu1>0.0001</mu1>
    <mu2>0.0001</mu2>
  </gazebo>

  <gazebo reference="rear_left_suspension">
    <mu1>0.0001</mu1>
    <mu2>0.0001</mu2>
  </gazebo>


  <gazebo reference="front_left_wheel">
    <mu1>1</mu1>
    <mu2>1</mu2>
  </gazebo>

  <gazebo reference="front_left_wheel">
    <mu1>1</mu1>
    <mu2>1</mu2>
  </gazebo>

  <gazebo>
    <plugin name="gazebo_ros_control" filename="libgazebo_ros_control.so">
      <robotNamespace>/toy_car2</robotNamespace>
    </plugin>
  </gazebo>

 <gazebo reference="lidar_top">
    <material>Gazebo/FlatBlack</material>
    <sensor type="ray" name="lds_lfcd_sensor">
      <pose>0 0 0 0 0 0</pose>
      <visualize>true</visualize>
      <update_rate>5</update_rate>
      <ray>
        <scan>
          <horizontal>
            <samples>360</samples>
            <resolution>1</resolution>
            <min_angle>0.0</min_angle>
            <max_angle>6.28319</max_angle>
          </horizontal>
        </scan>
        <range>
          <min>0.120</min>
          <max>3.5</max>
          <resolution>0.015</resolution>
        </range>
        <noise>
          <type>gaussian</type>
          <mean>0.0</mean>
          <stddev>0.01</stddev>
        </noise>
      </ray>
      <plugin name="gazebo_ros_lds_lfcd_controller" filename="libgazebo_ros_laser.so">
        <topicName>scan</topicName>
        <frameName>lidar_top</frameName>
      </plugin>
    </sensor>
  </gazebo>

<gazebo reference="camera_left">
    <sensor type="depth" name="realsense_R200">
      <always_on>true</always_on>
      <visualize>true</visualize>
      <camera>
          <horizontal_fov>1.3439</horizontal_fov>
          <image>
              <width>1920</width>
              <height>1080</height>
              <format>R8G8B8</format>
          </image>
          <depth_camera></depth_camera>
          <clip>
              <near>0.03</near>
              <far>100</far>
          </clip>
      </camera>
      <plugin name="camera_controller" filename="libgazebo_ros_openni_kinect.so">
        <baseline>0.2</baseline>
        <alwaysOn>true</alwaysOn>
        <updateRate>30.0</updateRate>
        <cameraName>camera_left</cameraName>
        <frameName>camera_rgb_optical_frame</frameName>
        <imageTopicName>rgb/image_raw</imageTopicName>
        <depthImageTopicName>depth/image_raw</depthImageTopicName>
        <pointCloudTopicName>depth/points</pointCloudTopicName>
        <cameraInfoTopicName>rgb/camera_info</cameraInfoTopicName>
        <depthImageCameraInfoTopicName>depth/camera_info</depthImageCameraInfoTopicName>
        <pointCloudCutoff>0.4</pointCloudCutoff>
            <hackBaseline>0.07</hackBaseline>
            <distortionK1>0.0</distortionK1>
            <distortionK2>0.0</distortionK2>
            <distortionK3>0.0</distortionK3>
            <distortionT1>0.0</distortionT1>
            <distortionT2>0.0</distortionT2>
        <CxPrime>0.0</CxPrime>
        <Cx>0.0</Cx>
        <Cy>0.0</Cy>
        <focalLength>0</focalLength>
        <hackBaseline>0</hackBaseline>
      </plugin>
    </sensor>
  </gazebo>

<gazebo reference="camera_center">
    <sensor type="depth" name="realsense_R200">
      <always_on>true</always_on>
      <visualize>true</visualize>
      <camera>
          <horizontal_fov>1.3439</horizontal_fov>
          <image>
              <width>1920</width>
              <height>1080</height>
              <format>R8G8B8</format>
          </image>
          <depth_camera></depth_camera>
          <clip>
              <near>0.03</near>
              <far>100</far>
          </clip>
      </camera>
      <plugin name="camera_controller" filename="libgazebo_ros_openni_kinect.so">
        <baseline>0.2</baseline>
        <alwaysOn>true</alwaysOn>
        <updateRate>30.0</updateRate>
        <cameraName>camera_center</cameraName>
        <frameName>camera_rgb_optical_frame</frameName>
        <imageTopicName>rgb/image_raw</imageTopicName>
        <depthImageTopicName>depth/image_raw</depthImageTopicName>
        <pointCloudTopicName>depth/points</pointCloudTopicName>
        <cameraInfoTopicName>rgb/camera_info</cameraInfoTopicName>
        <depthImageCameraInfoTopicName>depth/camera_info</depthImageCameraInfoTopicName>
        <pointCloudCutoff>0.4</pointCloudCutoff>
            <hackBaseline>0.07</hackBaseline>
            <distortionK1>0.0</distortionK1>
            <distortionK2>0.0</distortionK2>
            <distortionK3>0.0</distortionK3>
            <distortionT1>0.0</distortionT1>
            <distortionT2>0.0</distortionT2>
        <CxPrime>0.0</CxPrime>
        <Cx>0.0</Cx>
        <Cy>0.0</Cy>
        <focalLength>0</focalLength>
        <hackBaseline>0</hackBaseline>
      </plugin>
    </sensor>
  </gazebo>

<gazebo reference="camera_right">
    <sensor type="depth" name="realsense_R200">
      <always_on>true</always_on>
      <visualize>true</visualize>
      <camera>
          <horizontal_fov>1.3439</horizontal_fov>
          <image>
              <width>1920</width>
              <height>1080</height>
              <format>R8G8B8</format>
          </image>
          <depth_camera></depth_camera>
          <clip>
              <near>0.03</near>
              <far>100</far>
          </clip>
      </camera>
      <plugin name="camera_controller" filename="libgazebo_ros_openni_kinect.so">
        <baseline>0.2</baseline>
        <alwaysOn>true</alwaysOn>
        <updateRate>30.0</updateRate>
        <cameraName>camera_right</cameraName>
        <frameName>camera_rgb_optical_frame</frameName>
        <imageTopicName>rgb/image_raw</imageTopicName>
        <depthImageTopicName>depth/image_raw</depthImageTopicName>
        <pointCloudTopicName>depth/points</pointCloudTopicName>
        <cameraInfoTopicName>rgb/camera_info</cameraInfoTopicName>
        <depthImageCameraInfoTopicName>depth/camera_info</depthImageCameraInfoTopicName>
        <pointCloudCutoff>0.4</pointCloudCutoff>
            <hackBaseline>0.07</hackBaseline>
            <distortionK1>0.0</distortionK1>
            <distortionK2>0.0</distortionK2>
            <distortionK3>0.0</distortionK3>
            <distortionT1>0.0</distortionT1>
            <distortionT2>0.0</distortionT2>
        <CxPrime>0.0</CxPrime>
        <Cx>0.0</Cx>
        <Cy>0.0</Cy>
        <focalLength>0</focalLength>
        <hackBaseline>0</hackBaseline>
      </plugin>
    </sensor>
  </gazebo>



</robot>
