<?xml version="1.0" encoding="utf-8"?>
<!-- This URDF was automatically created by SolidWorks to URDF Exporter! Originally created by Stephen Brawner (brawner@gmail.com) 
     Commit Version:   Build Version: 1.5.7444.6699
     For more information, please see http://wiki.ros.org/sw_urdf_exporter -->
<robot
  name="toy_car2">
  <link
    name="base_link">
    <inertial>
      <origin
        xyz="-0.127630892992265 -2.0390722599295E-07 0.061739253269578"
        rpy="0 0 0" />
      <mass
        value="1.44712978241803" />
      <inertia
        ixx="0.00404346742409199"
        ixy="4.37499901540781E-12"
        ixz="9.49841862035702E-06"
        iyy="0.0020503900351124"
        iyz="-9.26470359601959E-12"
        izz="0.00567633439418209" />
    </inertial>
    <visual>
      <origin
        xyz="0 0 0"
        rpy="0 0 0" />
      <geometry>
        <mesh
          filename="package://toy_car/meshes/base_link.STL" />
      </geometry>
      <material
        name="">
        <color
          rgba="1 1 1 1" />
      </material>
    </visual>
    <collision>
      <origin
        xyz="0 0 0"
        rpy="0 0 0" />
      <geometry>
        <mesh
          filename="package://toy_car/meshes/base_link.STL" />
      </geometry>
    </collision>
  </link>
  <link
    name="front_left">
    <inertial>
      <origin
        xyz="-2.42861286636753E-17 0.0153267239617477 -0.00621293030951706"
        rpy="0 0 0" />
      <mass
        value="0.0211105794692306" />
      <inertia
        ixx="2.45369235482972E-06"
        ixy="-2.06936146205592E-21"
        ixz="3.81908817098804E-21"
        iyy="6.08127961989931E-06"
        iyz="3.66094605714795E-08"
        izz="6.08949128777742E-06" />
    </inertial>
    <visual>
      <origin
        xyz="0 0 0"
        rpy="0 0 0" />
      <geometry>
        <mesh
          filename="package://toy_car/meshes/front_left.STL" />
      </geometry>
      <material
        name="">
        <color
          rgba="0.898039215686275 0.917647058823529 0.929411764705882 1" />
      </material>
    </visual>
    <collision>
      <origin
        xyz="0 0 0"
        rpy="0 0 0" />
      <geometry>
        <mesh
          filename="package://toy_car/meshes/front_left.STL" />
      </geometry>
    </collision>
  </link>
  <joint
    name="front_left_joint"
    type="fixed">
    <origin
      xyz="-0.021 0.125 0.11499737041193"
      rpy="0 0 0" />
    <parent
      link="base_link" />
    <child
      link="front_left" />
    <axis
      xyz="0 0 0" />
  </joint>
  <link
    name="front_left_suspension">
    <inertial>
      <origin
        xyz="1.41212986311881E-05 0.00456072062457186 -0.0195885393740494"
        rpy="0 0 0" />
      <mass
        value="0.108487939485068" />
      <inertia
        ixx="2.53331074755856E-05"
        ixy="-1.61707386962673E-08"
        ixz="-5.78964187853838E-10"
        iyy="2.81997784693636E-05"
        iyz="-6.3079903539608E-07"
        izz="1.37874536494029E-05" />
    </inertial>
    <visual>
      <origin
        xyz="0 0 0"
        rpy="0 0 0" />
      <geometry>
        <mesh
          filename="package://toy_car/meshes/front_left_suspension.STL" />
      </geometry>
      <material
        name="">
        <color
          rgba="0.898039215686275 0.917647058823529 0.929411764705882 1" />
      </material>
    </visual>
    <collision>
      <origin
        xyz="0 0 0"
        rpy="0 0 0" />
      <geometry>
        <mesh
          filename="package://toy_car/meshes/front_left_suspension.STL" />
      </geometry>
    </collision>
  </link>
  <joint
    name="front_left_suspension_joint"
    type="prismatic">
    <origin
      xyz="0 0.0273428886495924 -0.07"
      rpy="0.17453292519943 0 0" />
    <parent
      link="front_left" />
    <child
      link="front_left_suspension" />
    <axis
      xyz="0 0 -1" />
    <limit
      lower="-0.03"
      upper="0.03"
      effort="30"
      velocity="100" />
  </joint>
  <link
    name="front_left_wheel">
    <inertial>
      <origin
        xyz="-1.21430643318376E-17 0.0200000000000001 0"
        rpy="0 0 0" />
      <mass
        value="0.389004584885853" />
      <inertia
        ixx="0.000724516969122224"
        ixy="-2.13436570141248E-19"
        ixz="5.87293933573465E-20"
        iyy="0.00137769204419062"
        iyz="2.53195099692233E-18"
        izz="0.000724516969122224" />
    </inertial>
    <visual>
      <origin
        xyz="0 0 0"
        rpy="0 0 0" />
      <geometry>
        <mesh
          filename="package://toy_car/meshes/front_left_wheel.STL" />
      </geometry>
      <material
        name="">
        <color
          rgba="1 1 1 1" />
      </material>
    </visual>
    <collision>
      <origin
        xyz="0 0 0"
        rpy="0 0 0" />
      <geometry>
        <mesh
          filename="package://toy_car/meshes/front_left_wheel.STL" />
      </geometry>
    </collision>
  </link>
  <joint
    name="front_left_wheel_joint"
    type="continuous">
    <origin
      xyz="1.12457305640069E-05 0.0310624201259151 -0.0649811422108027"
      rpy="-0.17453292519943 0 0" />
    <parent
      link="front_left_suspension" />
    <child
      link="front_left_wheel" />
    <axis
      xyz="0 1 0" />
    <limit
      effort="3.1"
      velocity="7" />
    <dynamics
      damping="0"
      friction="0" />
  </joint>
  <link
    name="front_right">
    <inertial>
      <origin
        xyz="-3.46944695195361E-18 -0.0153267239617477 -0.00621293030951707"
        rpy="0 0 0" />
      <mass
        value="0.0211105794692306" />
      <inertia
        ixx="2.45369235482973E-06"
        ixy="-1.26381602057167E-21"
        ixz="2.11877234587118E-21"
        iyy="6.08127961989932E-06"
        iyz="-3.66094605714801E-08"
        izz="6.08949128777743E-06" />
    </inertial>
    <visual>
      <origin
        xyz="0 0 0"
        rpy="0 0 0" />
      <geometry>
        <mesh
          filename="package://toy_car/meshes/front_right.STL" />
      </geometry>
      <material
        name="">
        <color
          rgba="0.792156862745098 0.819607843137255 0.933333333333333 1" />
      </material>
    </visual>
    <collision>
      <origin
        xyz="0 0 0"
        rpy="0 0 0" />
      <geometry>
        <mesh
          filename="package://toy_car/meshes/front_right.STL" />
      </geometry>
    </collision>
  </link>
  <joint
    name="front_right_joint"
    type="fixed">
    <origin
      xyz="-0.021 -0.125 0.11499737041193"
      rpy="0 0 0" />
    <parent
      link="base_link" />
    <child
      link="front_right" />
    <axis
      xyz="0 0 0" />
  </joint>
  <link
    name="front_right_suspension">
    <inertial>
      <origin
        xyz="1.41220467601705E-05 -0.00456072132070079 -0.0195885147601963"
        rpy="0 0 0" />
      <mass
        value="0.108487813658331" />
      <inertia
        ixx="2.53330676917247E-05"
        ixy="1.61694892194818E-08"
        ixz="-5.7875413875246E-10"
        iyy="2.81997446637394E-05"
        iyz="6.30812828016153E-07"
        izz="1.37874302271122E-05" />
    </inertial>
    <visual>
      <origin
        xyz="0 0 0"
        rpy="0 0 0" />
      <geometry>
        <mesh
          filename="package://toy_car/meshes/front_right_suspension.STL" />
      </geometry>
      <material
        name="">
        <color
          rgba="0.792156862745098 0.819607843137255 0.933333333333333 1" />
      </material>
    </visual>
    <collision>
      <origin
        xyz="0 0 0"
        rpy="0 0 0" />
      <geometry>
        <mesh
          filename="package://toy_car/meshes/front_right_suspension.STL" />
      </geometry>
    </collision>
  </link>
  <joint
    name="front_right_suspension_joint"
    type="prismatic">
    <origin
      xyz="0 -0.0273428886495923 -0.07"
      rpy="-0.17453292519943 0 0" />
    <parent
      link="front_right" />
    <child
      link="front_right_suspension" />
    <axis
      xyz="0 0 -1" />
    <limit
      lower="-0.03"
      upper="0.03"
      effort="30"
      velocity="100" />
  </joint>
  <link
    name="front_right_wheel">
    <inertial>
      <origin
        xyz="6.93889390390723E-18 -0.02 -6.93889390390723E-17"
        rpy="0 0 0" />
      <mass
        value="0.389004584885853" />
      <inertia
        ixx="0.000724516969122223"
        ixy="-2.14176334320512E-19"
        ixz="5.26568288700261E-21"
        iyy="0.00137769204419062"
        iyz="2.55290264909969E-18"
        izz="0.000724516969122223" />
    </inertial>
    <visual>
      <origin
        xyz="0 0 0"
        rpy="0 0 0" />
      <geometry>
        <mesh
          filename="package://toy_car/meshes/front_right_wheel.STL" />
      </geometry>
      <material
        name="">
        <color
          rgba="0.792156862745098 0.819607843137255 0.933333333333333 1" />
      </material>
    </visual>
    <collision>
      <origin
        xyz="0 0 0"
        rpy="0 0 0" />
      <geometry>
        <mesh
          filename="package://toy_car/meshes/front_right_wheel.STL" />
      </geometry>
    </collision>
  </link>
  <joint
    name="front_right_wheel_joint"
    type="continuous">
    <origin
      xyz="1.1246E-05 -0.031062 -0.064981"
      rpy="0.17453 0 0" />
    <parent
      link="front_right_suspension" />
    <child
      link="front_right_wheel" />
    <axis
      xyz="0 1 0" />
    <limit
      effort="3.1"
      velocity="7" />
    <dynamics
      damping="0"
      friction="0" />
  </joint>
  <link
    name="rear_left">
    <inertial>
      <origin
        xyz="0 5.55111512312578E-17 -0.0153728572796044"
        rpy="0 0 0" />
      <mass
        value="0.00600385822447067" />
      <inertia
        ixx="1.44009513612279E-06"
        ixy="-6.21347011227667E-23"
        ixz="-3.38630138596155E-23"
        iyy="5.05998771239394E-07"
        iyz="-2.62489462342665E-22"
        izz="1.54583669239748E-06" />
    </inertial>
    <visual>
      <origin
        xyz="0 0 0"
        rpy="0 0 0" />
      <geometry>
        <mesh
          filename="package://toy_car/meshes/rear_left.STL" />
      </geometry>
      <material
        name="">
        <color
          rgba="1 1 1 1" />
      </material>
    </visual>
    <collision>
      <origin
        xyz="0 0 0"
        rpy="0 0 0" />
      <geometry>
        <mesh
          filename="package://toy_car/meshes/rear_left.STL" />
      </geometry>
    </collision>
  </link>
  <joint
    name="rear_left_joint"
    type="fixed">
    <origin
      xyz="-0.2885 0.1025 0.0564"
      rpy="0 0 0" />
    <parent
      link="base_link" />
    <child
      link="rear_left" />
    <axis
      xyz="0 0 0" />
  </joint>
  <link
    name="rear_left_suspension">
    <inertial>
      <origin
        xyz="-5.55111512312578E-17 5.55111512312578E-17 -0.0367344920646688"
        rpy="0 0 0" />
      <mass
        value="0.0912015925296314" />
      <inertia
        ixx="5.37833661724247E-05"
        ixy="3.63073711914301E-21"
        ixz="-3.70073784649579E-21"
        iyy="5.3548912058809E-05"
        iyz="2.47320799558566E-21"
        izz="5.50897764645652E-05" />
    </inertial>
    <visual>
      <origin
        xyz="0 0 0"
        rpy="0 0 0" />
      <geometry>
        <mesh
          filename="package://toy_car/meshes/rear_left_suspension.STL" />
      </geometry>
      <material
        name="">
        <color
          rgba="1 1 1 1" />
      </material>
    </visual>
    <collision>
      <origin
        xyz="0 0 0"
        rpy="0 0 0" />
      <geometry>
        <mesh
          filename="package://toy_car/meshes/rear_left_suspension.STL" />
      </geometry>
    </collision>
  </link>
  <joint
    name="rear_left_suspension_joint"
    type="prismatic">
    <origin
      xyz="0 0 -0.06"
      rpy="0 0 0" />
    <parent
      link="rear_left" />
    <child
      link="rear_left_suspension" />
    <axis
      xyz="0 0 -1" />
    <limit
      lower="-0.02"
      upper="0.02"
      effort="30"
      velocity="100" />
    <dynamics
      damping="0"
      friction="0" />
  </joint>
  <link
    name="rear_right">
    <inertial>
      <origin
        xyz="0 0 -0.0153728572796044"
        rpy="0 0 0" />
      <mass
        value="0.00600385822447067" />
      <inertia
        ixx="1.4400951361228E-06"
        ixy="8.58820891122181E-24"
        ixz="-1.87231970863262E-22"
        iyy="5.05998771239395E-07"
        iyz="1.58079823192896E-22"
        izz="1.54583669239748E-06" />
    </inertial>
    <visual>
      <origin
        xyz="0 0 0"
        rpy="0 0 0" />
      <geometry>
        <mesh
          filename="package://toy_car/meshes/rear_right.STL" />
      </geometry>
      <material
        name="">
        <color
          rgba="0.792156862745098 0.819607843137255 0.933333333333333 1" />
      </material>
    </visual>
    <collision>
      <origin
        xyz="0 0 0"
        rpy="0 0 0" />
      <geometry>
        <mesh
          filename="package://toy_car/meshes/rear_right.STL" />
      </geometry>
    </collision>
  </link>
  <joint
    name="rear_right_joint"
    type="fixed">
    <origin
      xyz="-0.2885 -0.1025 0.0564"
      rpy="0 0 0" />
    <parent
      link="base_link" />
    <child
      link="rear_right" />
    <axis
      xyz="0 0 0" />
  </joint>
  <link
    name="rear_right_suspension">
    <inertial>
      <origin
        xyz="-1.11022302462516E-16 -1.23165366794353E-16 -0.0367344920646688"
        rpy="0 0 0" />
      <mass
        value="0.0912015925296314" />
      <inertia
        ixx="5.37833661724247E-05"
        ixy="-8.96300554573711E-22"
        ixz="-6.10880941463174E-21"
        iyy="5.3548912058809E-05"
        iyz="-1.06228182781035E-20"
        izz="5.50897764645652E-05" />
    </inertial>
    <visual>
      <origin
        xyz="0 0 0"
        rpy="0 0 0" />
      <geometry>
        <mesh
          filename="package://toy_car/meshes/rear_right_suspension.STL" />
      </geometry>
      <material
        name="">
        <color
          rgba="0.792156862745098 0.819607843137255 0.933333333333333 1" />
      </material>
    </visual>
    <collision>
      <origin
        xyz="0 0 0"
        rpy="0 0 0" />
      <geometry>
        <mesh
          filename="package://toy_car/meshes/rear_right_suspension.STL" />
      </geometry>
    </collision>
  </link>
  <joint
    name="rear_right_suspension_joint"
    type="prismatic">
    <origin
      xyz="0 0 -0.06"
      rpy="0 0 0" />
    <parent
      link="rear_right" />
    <child
      link="rear_right_suspension" />
    <axis
      xyz="0 0 -1" />
    <limit
      lower="-0.02"
      upper="0.02"
      effort="30"
      velocity="100" />
    <dynamics
      damping="0"
      friction="0" />
  </joint>
  <link
    name="camera_left">
    <inertial>
      <origin
        xyz="-0.012054 -2.6437E-06 0.0012903"
        rpy="0 0 0" />
      <mass
        value="0.061453" />
      <inertia
        ixx="2.3571E-05"
        ixy="-1.0181E-09"
        ixz="2.1758E-08"
        iyy="4.2948E-06"
        iyz="-8.8579E-10"
        izz="2.2106E-05" />
    </inertial>
    <visual>
      <origin
        xyz="0 0 0"
        rpy="0 0 0" />
      <geometry>
        <mesh
          filename="package://toy_car/meshes/camera_left.STL" />
      </geometry>
      <material
        name="">
        <color
          rgba="0.79216 0.81961 0.93333 1" />
      </material>
    </visual>
    <collision>
      <origin
        xyz="0 0 0"
        rpy="0 0 0" />
      <geometry>
        <mesh
          filename="package://toy_car/meshes/camera_left.STL" />
      </geometry>
    </collision>
  </link>
  <joint
    name="camera_left_joint"
    type="fixed">
    <origin
      xyz="0.0245 0.125 0.11"
      rpy="0 0 0" />
    <parent
      link="base_link" />
    <child
      link="camera_left" />
    <axis
      xyz="0 0 0" />
  </joint>
  <link
    name="camera_link">
    <inertial>
      <origin
        xyz="-9.6414E-05 -2.7168E-08 -0.010763"
        rpy="0 0 0" />
      <mass
        value="0.056857" />
      <inertia
        ixx="6.2815E-06"
        ixy="5.4446E-12"
        ixz="6.3778E-07"
        iyy="9.6719E-06"
        iyz="-1.6026E-13"
        izz="1.4883E-05" />
    </inertial>
    <visual>
      <origin
        xyz="0 0 0"
        rpy="0 0 0" />
      <geometry>
        <mesh
          filename="package://toy_car/meshes/camera_link.STL" />
      </geometry>
      <material
        name="">
        <color
          rgba="0.79216 0.81961 0.93333 1" />
      </material>
    </visual>
    <collision>
      <origin
        xyz="0 0 0"
        rpy="0 0 0" />
      <geometry>
        <mesh
          filename="package://toy_car/meshes/camera_link.STL" />
      </geometry>
    </collision>
  </link>
  <joint
    name="camera_link_joint"
    type="fixed">
    <origin
      xyz="0.027007 0 0.105"
      rpy="0 0 0" />
    <parent
      link="base_link" />
    <child
      link="camera_link" />
    <axis
      xyz="0 0 0" />
  </joint>
  <link
    name="camera_center">
    <inertial>
      <origin
        xyz="-0.012054 -2.6444E-06 0.0012903"
        rpy="0 0 0" />
      <mass
        value="0.061453" />
      <inertia
        ixx="2.3571E-05"
        ixy="-1.0184E-09"
        ixz="2.1759E-08"
        iyy="4.2948E-06"
        iyz="-8.8503E-10"
        izz="2.2106E-05" />
    </inertial>
    <visual>
      <origin
        xyz="0 0 0"
        rpy="0 0 0" />
      <geometry>
        <mesh
          filename="package://toy_car/meshes/camera_center.STL" />
      </geometry>
      <material
        name="">
        <color
          rgba="0.79216 0.81961 0.93333 1" />
      </material>
    </visual>
    <collision>
      <origin
        xyz="0 0 0"
        rpy="0 0 0" />
      <geometry>
        <mesh
          filename="package://toy_car/meshes/camera_center.STL" />
      </geometry>
    </collision>
  </link>
  <joint
    name="camera_center_joint"
    type="fixed">
    <origin
      xyz="0.0383297438164813 0 0.00819952580620682"
      rpy="0 0.201198652587711 0" />
    <parent
      link="camera_link" />
    <child
      link="camera_center" />
    <axis
      xyz="0 0 0" />
  </joint>
  <link
    name="camera_right">
    <inertial>
      <origin
        xyz="-0.012054 -2.6437E-06 0.0012903"
        rpy="0 0 0" />
      <mass
        value="0.061453" />
      <inertia
        ixx="2.3571E-05"
        ixy="-1.0181E-09"
        ixz="2.1758E-08"
        iyy="4.2948E-06"
        iyz="-8.8579E-10"
        izz="2.2106E-05" />
    </inertial>
    <visual>
      <origin
        xyz="0 0 0"
        rpy="0 0 0" />
      <geometry>
        <mesh
          filename="package://toy_car/meshes/camera_right.STL" />
      </geometry>
      <material
        name="">
        <color
          rgba="0.79216 0.81961 0.93333 1" />
      </material>
    </visual>
    <collision>
      <origin
        xyz="0 0 0"
        rpy="0 0 0" />
      <geometry>
        <mesh
          filename="package://toy_car/meshes/camera_right.STL" />
      </geometry>
    </collision>
  </link>
  <joint
    name="camera_right_joint"
    type="fixed">
    <origin
      xyz="0.0245 -0.125 0.11"
      rpy="0 0 0" />
    <parent
      link="base_link" />
    <child
      link="camera_right" />
    <axis
      xyz="0 0 0" />
  </joint>
  <link
    name="lidar_top">
    <inertial>
      <origin
        xyz="-0.01205 0.00052766 -0.028765"
        rpy="0 0 0" />
      <mass
        value="0.2" />
      <inertia
        ixx="1.9581E-05"
        ixy="-1.0393E-07"
        ixz="4.2839E-07"
        iyy="2.4125E-05"
        iyz="-9.4271E-09"
        izz="4.1418E-05" />
    </inertial>
    <visual>
      <origin
        xyz="0 0 0"
        rpy="0 0 0" />
      <geometry>
        <mesh
          filename="package://toy_car/meshes/lidar_top.STL" />
      </geometry>
      <material
        name="">
        <color
          rgba="0.79216 0.81961 0.93333 1" />
      </material>
    </visual>
    <collision>
      <origin
        xyz="0 0 0"
        rpy="0 0 0" />
      <geometry>
        <mesh
          filename="package://toy_car/meshes/lidar_top.STL" />
      </geometry>
    </collision>
  </link>
  <joint
    name="lidar_top_joint"
    type="fixed">
    <origin
      xyz="-0.085232 0 0.177"
      rpy="0 0 0" />
    <parent
      link="base_link" />
    <child
      link="lidar_top" />
    <axis
      xyz="0 0 0" />
  </joint>
  <link
    name="imu">
    <inertial>
      <origin
        xyz="8.6736E-19 -2.7756E-17 -0.005"
        rpy="0 0 0" />
      <mass
        value="0.001" />
      <inertia
        ixx="1.6667E-08"
        ixy="2.2488E-24"
        ixz="5.5145E-25"
        iyy="1.6667E-08"
        iyz="-3.5332E-25"
        izz="1.6667E-08" />
    </inertial>
    <visual>
      <origin
        xyz="0 0 0"
        rpy="0 0 0" />
      <geometry>
        <mesh
          filename="package://toy_car/meshes/imu.STL" />
      </geometry>
      <material
        name="">
        <color
          rgba="0.79216 0.81961 0.93333 1" />
      </material>
    </visual>
    <collision>
      <origin
        xyz="0 0 0"
        rpy="0 0 0" />
      <geometry>
        <mesh
          filename="package://toy_car/meshes/imu.STL" />
      </geometry>
    </collision>
  </link>
  <joint
    name="imu_joint"
    type="fixed">
    <origin
      xyz="-0.005 0 0.135"
      rpy="0 0 0" />
    <parent
      link="base_link" />
    <child
      link="imu" />
    <axis
      xyz="0 0 0" />
  </joint>
  <link
    name="holder">
    <inertial>
      <origin
        xyz="0.057751 -6.9944E-15 -0.0067357"
        rpy="0 0 0" />
      <mass
        value="1.432834" />
      <inertia
        ixx="0.0054116"
        ixy="-7.1151E-19"
        ixz="-6.8086E-05"
        iyy="0.0011892"
        iyz="-1.7025E-19"
        izz="0.0061799" />
    </inertial>
    <visual>
      <origin
        xyz="0 0 0"
        rpy="0 0 0" />
      <geometry>
        <mesh
          filename="package://toy_car/meshes/holder.STL" />
      </geometry>
      <material
        name="">
        <color
          rgba="0.89804 0.91765 0.92941 1" />
      </material>
    </visual>
    <collision>
      <origin
        xyz="0 0 0"
        rpy="0 0 0" />
      <geometry>
        <mesh
          filename="package://toy_car/meshes/holder.STL" />
      </geometry>
    </collision>
  </link>
  <joint
    name="holder_joint"
    type="fixed">
    <origin
      xyz="0.0015 0 0.019999"
      rpy="0 0 0" />
    <parent
      link="base_link" />
    <child
      link="holder" />
    <axis
      xyz="0 0 0" />
  </joint>
  <link
    name="nuc">
    <inertial>
      <origin
        xyz="0.00042147 5.6775E-05 0.015867"
        rpy="0 0 0" />
      <mass
        value="0.39954" />
      <inertia
        ixx="0.00047302"
        ixy="-3.1716E-07"
        ixz="-4.7745E-07"
        iyy="0.00043203"
        iyz="1.8338E-07"
        izz="0.00083697" />
    </inertial>
    <visual>
      <origin
        xyz="0 0 0"
        rpy="0 0 0" />
      <geometry>
        <mesh
          filename="package://toy_car/meshes/nuc.STL" />
      </geometry>
      <material
        name="">
        <color
          rgba="0.79216 0.81961 0.93333 1" />
      </material>
    </visual>
    <collision>
      <origin
        xyz="0 0 0"
        rpy="0 0 0" />
      <geometry>
        <mesh
          filename="package://toy_car/meshes/nuc.STL" />
      </geometry>
    </collision>
  </link>
  <joint
    name="nuc_joint"
    type="fixed">
    <origin
      xyz="-0.073998 7.38E-05 0.0071"
      rpy="0 0 0" />
    <parent
      link="base_link" />
    <child
      link="nuc" />
    <axis
      xyz="0 0 0" />
  </joint>
  <link
    name="rio">
    <inertial>
      <origin
        xyz="-5.9245E-05 -0.00039133 0.011832"
        rpy="0 0 0" />
      <mass
        value="0.193" />
      <inertia
        ixx="0.0004265"
        ixy="1.3278E-06"
        ixz="-1.3394E-07"
        iyy="0.00018312"
        iyz="9.7818E-08"
        izz="0.00058403" />
    </inertial>
    <visual>
      <origin
        xyz="0 0 0"
        rpy="0 0 0" />
      <geometry>
        <mesh
          filename="package://toy_car/meshes/rio.STL" />
      </geometry>
      <material
        name="">
        <color
          rgba="0.14902 0.14902 0.14902 1" />
      </material>
    </visual>
    <collision>
      <origin
        xyz="0 0 0"
        rpy="0 0 0" />
      <geometry>
        <mesh
          filename="package://toy_car/meshes/rio.STL" />
      </geometry>
    </collision>
  </link>
  <joint
    name="rio_joint"
    type="fixed">
    <origin
      xyz="-0.062748 0 0.0391"
      rpy="0 0 0" />
    <parent
      link="base_link" />
    <child
      link="rio" />
    <axis
      xyz="0 0 0" />
  </joint>
  <link
    name="jetson">
    <inertial>
      <origin
        xyz="0.013425 -0.004013 0.015834"
        rpy="0 0 0" />
      <mass
        value="0.2" />
      <inertia
        ixx="0.00039935"
        ixy="2.9288E-07"
        ixz="1.1281E-08"
        iyy="0.00035768"
        iyz="-7.0335E-09"
        izz="0.00074652" />
    </inertial>
    <visual>
      <origin
        xyz="0 0 0"
        rpy="0 0 0" />
      <geometry>
        <mesh
          filename="package://toy_car/meshes/jetson.STL" />
      </geometry>
      <material
        name="">
        <color
          rgba="0.79216 0.81961 0.93333 1" />
      </material>
    </visual>
    <collision>
      <origin
        xyz="0 0 0"
        rpy="0 0 0" />
      <geometry>
        <mesh
          filename="package://toy_car/meshes/jetson.STL" />
      </geometry>
    </collision>
  </link>
  <joint
    name="jetson_joint"
    type="fixed">
    <origin
      xyz="-0.1085 0 0.0671"
      rpy="0 0 0" />
    <parent
      link="base_link" />
    <child
      link="jetson" />
    <axis
      xyz="0 0 0" />
  </joint>
  <link
    name="dummy">
    <inertial>
      <origin
        xyz="0 0 0"
        rpy="0 0 0" />
      <mass
        value="0" />
      <inertia
        ixx="0"
        ixy="0"
        ixz="0"
        iyy="0"
        iyz="0"
        izz="0" />
    </inertial>
    <visual>
      <origin
        xyz="0 0 0"
        rpy="0 0 0" />
      <geometry>
        <mesh
          filename="package://toy_car/meshes/dummy.STL" />
      </geometry>
      <material
        name="">
        <color
          rgba="1 1 1 1" />
      </material>
    </visual>
    <collision>
      <origin
        xyz="0 0 0"
        rpy="0 0 0" />
      <geometry>
        <mesh
          filename="package://toy_car/meshes/dummy.STL" />
      </geometry>
    </collision>
  </link>
  <joint
    name="dummy_joint"
    type="fixed">
    <origin
      xyz="-0.00499999999999977 0 0.13499737041193"
      rpy="0 0 0" />
    <parent
      link="base_link" />
    <child
      link="dummy" />
    <axis
      xyz="0 0 0" />
  </joint>





  <transmission name="tran_left_wheel">
    <type>transmission_interface/SimpleTransmission</type>
    <joint name="front_left_wheel_joint">
      <hardwareInterface>VelocityJointInterface</hardwareInterface>
    </joint>
    <actuator name="motor1">
      <hardwareInterface>VelocityJointInterface</hardwareInterface>
      <mechanicalReduction>1</mechanicalReduction>
    </actuator>
  </transmission>

  <transmission name="tran_right_wheel">
    <type>transmission_interface/SimpleTransmission</type>
    <joint name="front_right_wheel_joint">
      <hardwareInterface>VelocityJointInterface</hardwareInterface>
    </joint>
    <actuator name="motor2">
      <hardwareInterface>VelocityJointInterface</hardwareInterface>
      <mechanicalReduction>1</mechanicalReduction>
    </actuator>
  </transmission>

  <transmission name="tran_front_left_sus">
    <type>transmission_interface/SimpleTransmission</type>
    <joint name="front_left_suspension_joint">
      <hardwareInterface>hardware_interface/EffortJointInterface</hardwareInterface>
    </joint>
    <actuator name="motor_sus1">
      <hardwareInterface>hardware_interface/EffortJointInterface</hardwareInterface>
      <mechanicalReduction>1</mechanicalReduction>
    </actuator>
  </transmission>

  <transmission name="tran_front_right_sus">
    <type>transmission_interface/SimpleTransmission</type>
    <joint name="front_right_suspension_joint">
      <hardwareInterface>hardware_interface/EffortJointInterface</hardwareInterface>
    </joint>
    <actuator name="motor_sus2">
      <hardwareInterface>hardware_interface/EffortJointInterface</hardwareInterface>
      <mechanicalReduction>1</mechanicalReduction>
    </actuator>
  </transmission>

  <transmission name="tran_rear_left_sus">
    <type>transmission_interface/SimpleTransmission</type>
    <joint name="rear_left_suspension_joint">
      <hardwareInterface>hardware_interface/EffortJointInterface</hardwareInterface>
    </joint>
    <actuator name="motor_sus3">
      <hardwareInterface>hardware_interface/EffortJointInterface</hardwareInterface>
      <mechanicalReduction>1</mechanicalReduction>
    </actuator>
  </transmission>

  <transmission name="tran_rear_right_sus">
    <type>transmission_interface/SimpleTransmission</type>
    <joint name="rear_right_suspension_joint">
      <hardwareInterface>hardware_interface/EffortJointInterface</hardwareInterface>
    </joint>
    <actuator name="motor_sus4">
      <hardwareInterface>hardware_interface/EffortJointInterface</hardwareInterface>
      <mechanicalReduction>1</mechanicalReduction>
    </actuator>
  </transmission>

  <gazebo reference="rear_right_suspension">
    <mu1>0.0001</mu1>
    <mu2>0.0001</mu2>
  </gazebo>

  <gazebo reference="rear_left_suspension">
    <mu1>0.0001</mu1>
    <mu2>0.0001</mu2>
  </gazebo>


  <gazebo reference="front_left_wheel">
    <mu1>1</mu1>
    <mu2>1</mu2>
  </gazebo>

  <gazebo reference="front_left_wheel">
    <mu1>1</mu1>
    <mu2>1</mu2>
  </gazebo>

  <gazebo>
    <plugin name="gazebo_ros_control" filename="libgazebo_ros_control.so">
      <robotNamespace>/toy_car2</robotNamespace>
    </plugin>
  </gazebo>

 <gazebo reference="lidar_top">
    <material>Gazebo/FlatBlack</material>
    <sensor type="ray" name="lds_lfcd_sensor">
      <pose>0 0 0 0 0 0</pose>
      <visualize>false</visualize>
      <update_rate>5</update_rate>
      <ray>
        <scan>
          <horizontal>
            <samples>360</samples>
            <resolution>1</resolution>
            <min_angle>0.0</min_angle>
            <max_angle>6.28319</max_angle>
          </horizontal>
        </scan>
        <range>
          <min>0.120</min>
          <max>3.5</max>
          <resolution>0.015</resolution>
        </range>
        <noise>
          <type>gaussian</type>
          <mean>0.0</mean>
          <stddev>0.01</stddev>
        </noise>
      </ray>
      <plugin name="gazebo_ros_lds_lfcd_controller" filename="libgazebo_ros_laser.so">
        <topicName>scan</topicName>
        <frameName>lidar_top</frameName>
      </plugin>
    </sensor>
  </gazebo>

<gazebo reference="camera_left">
    <sensor type="depth" name="realsense_R200">
      <always_on>true</always_on>
      <visualize>true</visualize>
      <camera>
          <horizontal_fov>1.3439</horizontal_fov>
          <image>
              <width>1920</width>
              <height>1080</height>
              <format>R8G8B8</format>
          </image>
          <depth_camera></depth_camera>
          <clip>
              <near>0.03</near>
              <far>100</far>
          </clip>
      </camera>
      <plugin name="camera_controller" filename="libgazebo_ros_openni_kinect.so">
        <baseline>0.2</baseline>
        <alwaysOn>true</alwaysOn>
        <updateRate>30.0</updateRate>
        <cameraName>camera_left</cameraName>
        <frameName>camera_rgb_optical_frame</frameName>
        <imageTopicName>rgb/image_raw</imageTopicName>
        <depthImageTopicName>depth/image_raw</depthImageTopicName>
        <pointCloudTopicName>depth/points</pointCloudTopicName>
        <cameraInfoTopicName>rgb/camera_info</cameraInfoTopicName>
        <depthImageCameraInfoTopicName>depth/camera_info</depthImageCameraInfoTopicName>
        <pointCloudCutoff>0.4</pointCloudCutoff>
            <hackBaseline>0.07</hackBaseline>
            <distortionK1>0.0</distortionK1>
            <distortionK2>0.0</distortionK2>
            <distortionK3>0.0</distortionK3>
            <distortionT1>0.0</distortionT1>
            <distortionT2>0.0</distortionT2>
        <CxPrime>0.0</CxPrime>
        <Cx>0.0</Cx>
        <Cy>0.0</Cy>
        <focalLength>0</focalLength>
        <hackBaseline>0</hackBaseline>
      </plugin>
    </sensor>
  </gazebo>

<gazebo reference="camera_center">
    <sensor type="depth" name="realsense_R200">
      <always_on>true</always_on>
      <visualize>true</visualize>
      <camera>
          <horizontal_fov>1.3439</horizontal_fov>
          <image>
              <width>1920</width>
              <height>1080</height>
              <format>R8G8B8</format>
          </image>
          <depth_camera></depth_camera>
          <clip>
              <near>0.03</near>
              <far>100</far>
          </clip>
      </camera>
      <plugin name="camera_controller" filename="libgazebo_ros_openni_kinect.so">
        <baseline>0.2</baseline>
        <alwaysOn>true</alwaysOn>
        <updateRate>30.0</updateRate>
        <cameraName>camera_center</cameraName>
        <frameName>camera_rgb_optical_frame</frameName>
        <imageTopicName>rgb/image_raw</imageTopicName>
        <depthImageTopicName>depth/image_raw</depthImageTopicName>
        <pointCloudTopicName>depth/points</pointCloudTopicName>
        <cameraInfoTopicName>rgb/camera_info</cameraInfoTopicName>
        <depthImageCameraInfoTopicName>depth/camera_info</depthImageCameraInfoTopicName>
        <pointCloudCutoff>0.4</pointCloudCutoff>
            <hackBaseline>0.07</hackBaseline>
            <distortionK1>0.0</distortionK1>
            <distortionK2>0.0</distortionK2>
            <distortionK3>0.0</distortionK3>
            <distortionT1>0.0</distortionT1>
            <distortionT2>0.0</distortionT2>
        <CxPrime>0.0</CxPrime>
        <Cx>0.0</Cx>
        <Cy>0.0</Cy>
        <focalLength>0</focalLength>
        <hackBaseline>0</hackBaseline>
      </plugin>
    </sensor>
  </gazebo>

<gazebo reference="camera_right">
    <sensor type="depth" name="realsense_R200">
      <always_on>true</always_on>
      <visualize>true</visualize>
      <camera>
          <horizontal_fov>1.3439</horizontal_fov>
          <image>
              <width>1920</width>
              <height>1080</height>
              <format>R8G8B8</format>
          </image>
          <depth_camera></depth_camera>
          <clip>
              <near>0.03</near>
              <far>100</far>
          </clip>
      </camera>
      <plugin name="camera_controller" filename="libgazebo_ros_openni_kinect.so">
        <baseline>0.2</baseline>
        <alwaysOn>true</alwaysOn>
        <updateRate>30.0</updateRate>
        <cameraName>camera_right</cameraName>
        <frameName>camera_rgb_optical_frame</frameName>
        <imageTopicName>rgb/image_raw</imageTopicName>
        <depthImageTopicName>depth/image_raw</depthImageTopicName>
        <pointCloudTopicName>depth/points</pointCloudTopicName>
        <cameraInfoTopicName>rgb/camera_info</cameraInfoTopicName>
        <depthImageCameraInfoTopicName>depth/camera_info</depthImageCameraInfoTopicName>
        <pointCloudCutoff>0.4</pointCloudCutoff>
            <hackBaseline>0.07</hackBaseline>
            <distortionK1>0.0</distortionK1>
            <distortionK2>0.0</distortionK2>
            <distortionK3>0.0</distortionK3>
            <distortionT1>0.0</distortionT1>
            <distortionT2>0.0</distortionT2>
        <CxPrime>0.0</CxPrime>
        <Cx>0.0</Cx>
        <Cy>0.0</Cy>
        <focalLength>0</focalLength>
        <hackBaseline>0</hackBaseline>
      </plugin>
    </sensor>
  </gazebo>




</robot>
