<?xml version="1.0" encoding="utf-8"?>
<!-- This URDF was automatically created by SolidWorks to URDF Exporter! Originally created by Stephen Brawner (brawner@gmail.com) 
     Commit Version:   Build Version: 1.5.7444.6699
     For more information, please see http://wiki.ros.org/sw_urdf_exporter -->
<robot
  name="toy_car2">
  <link
    name="base_link">
    <inertial>
      <origin
        xyz="-0.0429725676225381 -0.000267178599244661 0.0471298420442132"
        rpy="0 0 0" />
      <mass
        value="3.81368362259093" />
      <inertia
        ixx="0.0114922800341374"
        ixy="1.2059249165165E-06"
        ixz="-1.88827417940258E-05"
        iyy="0.0038360950287992"
        iyz="2.87540667009997E-07"
        izz="0.0146500038054547" />
    </inertial>
    <visual>
      <origin
        xyz="0 0 0"
        rpy="0 0 0" />
      <geometry>
        <mesh
          filename="package://toy_car/meshes/base_link.STL" />
      </geometry>
      <material
        name="">
        <color
          rgba="0.898039215686275 0.917647058823529 0.929411764705882 1" />
      </material>
    </visual>
    <collision>
      <origin
        xyz="0 0 0"
        rpy="0 0 0" />
      <geometry>
        <mesh
          filename="package://toy_car/meshes/base_link.STL" />
      </geometry>
    </collision>
  </link>
  <link
    name="front_left">
    <inertial>
      <origin
        xyz="-2.42861286636753E-17 0.0153267239617477 -0.00621293030951706"
        rpy="0 0 0" />
      <mass
        value="0.0211105794692306" />
      <inertia
        ixx="2.45369235482972E-06"
        ixy="-2.07990699631126E-21"
        ixz="3.78132321519841E-21"
        iyy="6.08127961989931E-06"
        iyz="3.66094605714796E-08"
        izz="6.08949128777742E-06" />
    </inertial>
    <visual>
      <origin
        xyz="0 0 0"
        rpy="0 0 0" />
      <geometry>
        <mesh
          filename="package://toy_car/meshes/front_left.STL" />
      </geometry>
      <material
        name="">
        <color
          rgba="0.898039215686275 0.917647058823529 0.929411764705882 1" />
      </material>
    </visual>
    <collision>
      <origin
        xyz="0 0 0"
        rpy="0 0 0" />
      <geometry>
        <mesh
          filename="package://toy_car/meshes/front_left.STL" />
      </geometry>
    </collision>
  </link>
  <joint
    name="front_left_joint"
    type="fixed">
    <origin
      xyz="-0.021 0.125 0.11499737041193"
      rpy="0 0 0" />
    <parent
      link="base_link" />
    <child
      link="front_left" />
    <axis
      xyz="0 0 0" />
  </joint>
  <link
    name="front_left_suspension">
    <inertial>
      <origin
        xyz="1.41212986311881E-05 0.0045607206245718 -0.0195885393740494"
        rpy="0 0 0" />
      <mass
        value="0.108487939485068" />
      <inertia
        ixx="2.53331074755856E-05"
        ixy="-1.61707386962674E-08"
        ixz="-5.78964187854019E-10"
        iyy="2.81997784693636E-05"
        iyz="-6.30799035396079E-07"
        izz="1.37874536494029E-05" />
    </inertial>
    <visual>
      <origin
        xyz="0 0 0"
        rpy="0 0 0" />
      <geometry>
        <mesh
          filename="package://toy_car/meshes/front_left_suspension.STL" />
      </geometry>
      <material
        name="">
        <color
          rgba="0.898039215686275 0.917647058823529 0.929411764705882 1" />
      </material>
    </visual>
    <collision>
      <origin
        xyz="0 0 0"
        rpy="0 0 0" />
      <geometry>
        <mesh
          filename="package://toy_car/meshes/front_left_suspension.STL" />
      </geometry>
    </collision>
  </link>
  <joint
    name="front_left_suspension_joint"
    type="prismatic">
    <origin
      xyz="0 0.0273428886495924 -0.07"
      rpy="0.17453292519943 0 0" />
    <parent
      link="front_left" />
    <child
      link="front_left_suspension" />
    <axis
      xyz="0 0 -1" />
    <limit
      lower="-0.03"
      upper="0.03"
      effort="1000"
      velocity="1000" />
    <dynamics
      damping="0"
      friction="0" />
  </joint>
  <link
    name="front_left_wheel">
    <inertial>
      <origin
        xyz="-2.08166817117217E-17 0.02 2.77555756156289E-17"
        rpy="0 0 0" />
      <mass
        value="0.389004584885854" />
      <inertia
        ixx="0.000724516969122224"
        ixy="-2.13604799360613E-19"
        ixz="5.42655297253163E-20"
        iyy="0.00137769204419062"
        iyz="2.53222282423438E-18"
        izz="0.000724516969122224" />
    </inertial>
    <visual>
      <origin
        xyz="0 0 0"
        rpy="0 0 0" />
      <geometry>
        <mesh
          filename="package://toy_car/meshes/front_left_wheel.STL" />
      </geometry>
      <material
        name="">
        <color
          rgba="1 1 1 1" />
      </material>
    </visual>
    <collision>
      <origin
        xyz="0 0 0"
        rpy="0 0 0" />
      <geometry>
        <mesh
          filename="package://toy_car/meshes/front_left_wheel.STL" />
      </geometry>
    </collision>
  </link>
  <joint
    name="front_left_wheel_joint"
    type="continuous">
    <origin
      xyz="1.12457305640069E-05 0.0310624201259151 -0.0649811422108027"
      rpy="-0.17453292519943 0 0" />
    <parent
      link="front_left_suspension" />
    <child
      link="front_left_wheel" />
    <axis
      xyz="0 1 0" />
    <limit
      effort="3.1"
      velocity="7" />
  </joint>
  <link
    name="front_right">
    <inertial>
      <origin
        xyz="3.29597460435593E-17 -0.0153267239617477 -0.00621293030951707"
        rpy="0 0 0" />
      <mass
        value="0.0211105794692306" />
      <inertia
        ixx="2.45369235482973E-06"
        ixy="6.71998739664856E-22"
        ixz="2.48729805711132E-21"
        iyy="6.08127961989933E-06"
        iyz="-3.6609460571481E-08"
        izz="6.08949128777743E-06" />
    </inertial>
    <visual>
      <origin
        xyz="0 0 0"
        rpy="0 0 0" />
      <geometry>
        <mesh
          filename="package://toy_car/meshes/front_right.STL" />
      </geometry>
      <material
        name="">
        <color
          rgba="0.898039215686275 0.917647058823529 0.929411764705882 1" />
      </material>
    </visual>
    <collision>
      <origin
        xyz="0 0 0"
        rpy="0 0 0" />
      <geometry>
        <mesh
          filename="package://toy_car/meshes/front_right.STL" />
      </geometry>
    </collision>
  </link>
  <joint
    name="front_right_joint"
    type="fixed">
    <origin
      xyz="-0.0210000000000001 -0.125 0.11499737041193"
      rpy="0 0 0" />
    <parent
      link="base_link" />
    <child
      link="front_right" />
    <axis
      xyz="0 0 0" />
  </joint>
  <link
    name="front_right_suspension">
    <inertial>
      <origin
        xyz="-1.4121298631176E-05 -0.00456072062457182 -0.0195885393740494"
        rpy="0 0 0" />
      <mass
        value="0.108487939485068" />
      <inertia
        ixx="2.53331074755856E-05"
        ixy="-1.61707386962753E-08"
        ixz="5.78964187846857E-10"
        iyy="2.81997784693636E-05"
        iyz="6.30799035396077E-07"
        izz="1.37874536494029E-05" />
    </inertial>
    <visual>
      <origin
        xyz="0 0 0"
        rpy="0 0 0" />
      <geometry>
        <mesh
          filename="package://toy_car/meshes/front_right_suspension.STL" />
      </geometry>
      <material
        name="">
        <color
          rgba="0.898039215686275 0.917647058823529 0.929411764705882 1" />
      </material>
    </visual>
    <collision>
      <origin
        xyz="0 0 0"
        rpy="0 0 0" />
      <geometry>
        <mesh
          filename="package://toy_car/meshes/front_right_suspension.STL" />
      </geometry>
    </collision>
  </link>
  <joint
    name="front_right_suspension_joint"
    type="prismatic">
    <origin
      xyz="0 -0.0273428886495923 -0.07"
      rpy="-0.17453292519943 0 0" />
    <parent
      link="front_right" />
    <child
      link="front_right_suspension" />
    <axis
      xyz="0 0 -1" />
    <limit
      lower="-0.03"
      upper="0.03"
      effort="1000"
      velocity="1000" />
    <dynamics
      damping="0"
      friction="0" />
  </joint>
  <link
    name="front_right_wheel">
    <inertial>
      <origin
        xyz="3.46944695195361E-18 -0.02 -6.93889390390723E-17"
        rpy="0 0 0" />
      <mass
        value="0.389004584885853" />
      <inertia
        ixx="0.000724516969122223"
        ixy="-2.0869319940662E-19"
        ixz="6.07790807408048E-21"
        iyy="0.00137769204419062"
        iyz="2.54100205603488E-18"
        izz="0.000724516969122223" />
    </inertial>
    <visual>
      <origin
        xyz="0 0 0"
        rpy="0 0 0" />
      <geometry>
        <mesh
          filename="package://toy_car/meshes/front_right_wheel.STL" />
      </geometry>
      <material
        name="">
        <color
          rgba="1 1 1 1" />
      </material>
    </visual>
    <collision>
      <origin
        xyz="0 0 0"
        rpy="0 0 0" />
      <geometry>
        <mesh
          filename="package://toy_car/meshes/front_right_wheel.STL" />
      </geometry>
    </collision>
  </link>
  <joint
    name="front_right_wheel_joint"
    type="continuous">
    <origin
      xyz="-1.1246E-05 -0.031062 -0.064981"
      rpy="0.17453 0 0" />
    <parent
      link="front_right_suspension" />
    <child
      link="front_right_wheel" />
    <axis
      xyz="0 1 0" />
    <limit
      effort="3.1"
      velocity="7" />
  </joint>
  <link
    name="rear_left">
    <inertial>
      <origin
        xyz="0 8.32667268468867E-17 -0.0153728572796044"
        rpy="0 0 0" />
      <mass
        value="0.00600385822447067" />
      <inertia
        ixx="1.44009513612279E-06"
        ixy="-6.21347011227668E-23"
        ixz="-3.38630138596155E-23"
        iyy="5.05998771239394E-07"
        iyz="-2.62489462342665E-22"
        izz="1.54583669239748E-06" />
    </inertial>
    <visual>
      <origin
        xyz="0 0 0"
        rpy="0 0 0" />
      <geometry>
        <mesh
          filename="package://toy_car/meshes/rear_left.STL" />
      </geometry>
      <material
        name="">
        <color
          rgba="1 1 1 1" />
      </material>
    </visual>
    <collision>
      <origin
        xyz="0 0 0"
        rpy="0 0 0" />
      <geometry>
        <mesh
          filename="package://toy_car/meshes/rear_left.STL" />
      </geometry>
    </collision>
  </link>
  <joint
    name="rear_left_joint"
    type="fixed">
    <origin
      xyz="-0.288495633593833 0.1025 0.0564000000000001"
      rpy="0 0 0" />
    <parent
      link="base_link" />
    <child
      link="rear_left" />
    <axis
      xyz="0 0 0" />
  </joint>
  <link
    name="rear_left_suspension">
    <inertial>
      <origin
        xyz="0 5.55111512312578E-17 -0.0393577295170233"
        rpy="0 0 0" />
      <mass
        value="0.0815242305195134" />
      <inertia
        ixx="5.03457524758413E-05"
        ixy="-2.73343613870472E-22"
        ixz="-2.69939333546856E-21"
        iyy="5.01112983622256E-05"
        iyz="2.51620724300096E-21"
        izz="4.8856497869962E-05" />
    </inertial>
    <visual>
      <origin
        xyz="0 0 0"
        rpy="0 0 0" />
      <geometry>
        <mesh
          filename="package://toy_car/meshes/rear_left_suspension.STL" />
      </geometry>
      <material
        name="">
        <color
          rgba="1 1 1 1" />
      </material>
    </visual>
    <collision>
      <origin
        xyz="0 0 0"
        rpy="0 0 0" />
      <geometry>
        <mesh
          filename="package://toy_car/meshes/rear_left_suspension.STL" />
      </geometry>
    </collision>
  </link>
  <joint
    name="rear_left_suspension_joint"
    type="prismatic">
    <origin
      xyz="0 0 -0.06"
      rpy="0 0 0" />
    <parent
      link="rear_left" />
    <child
      link="rear_left_suspension" />
    <axis
      xyz="0 0 -1" />
    <limit
      lower="-0.02"
      upper="0.02"
      effort="1000"
      velocity="1000" />
    <dynamics
      damping="0"
      friction="0" />
  </joint>
  <link
    name="rear_right">
    <inertial>
      <origin
        xyz="0 -5.20417042793042E-18 -0.0153728572796044"
        rpy="0 0 0" />
      <mass
        value="0.00600385822447067" />
      <inertia
        ixx="1.4400951361228E-06"
        ixy="1.56504335592465E-22"
        ixz="-4.39618613232038E-23"
        iyy="5.05998771239394E-07"
        iyz="-7.69360318009659E-23"
        izz="1.54583669239748E-06" />
    </inertial>
    <visual>
      <origin
        xyz="0 0 0"
        rpy="0 0 0" />
      <geometry>
        <mesh
          filename="package://toy_car/meshes/rear_right.STL" />
      </geometry>
      <material
        name="">
        <color
          rgba="1 1 1 1" />
      </material>
    </visual>
    <collision>
      <origin
        xyz="0 0 0"
        rpy="0 0 0" />
      <geometry>
        <mesh
          filename="package://toy_car/meshes/rear_right.STL" />
      </geometry>
    </collision>
  </link>
  <joint
    name="rear_right"
    type="fixed">
    <origin
      xyz="-0.288495633593834 -0.1025 0.0564000000000001"
      rpy="0 0 0" />
    <parent
      link="base_link" />
    <child
      link="rear_right" />
    <axis
      xyz="0 0 0" />
  </joint>
  <link
    name="rear_right_suspension">
    <inertial>
      <origin
        xyz="0 -1.04083408558608E-17 -0.0393577295170232"
        rpy="0 0 0" />
      <mass
        value="0.0815242305195134" />
      <inertia
        ixx="5.03457524758413E-05"
        ixy="-7.45258625197246E-23"
        ixz="9.46617793312654E-23"
        iyy="5.01112983622256E-05"
        iyz="-1.4837703661536E-22"
        izz="4.8856497869962E-05" />
    </inertial>
    <visual>
      <origin
        xyz="0 0 0"
        rpy="0 0 0" />
      <geometry>
        <mesh
          filename="package://toy_car/meshes/rear_right_suspension.STL" />
      </geometry>
      <material
        name="">
        <color
          rgba="1 1 1 1" />
      </material>
    </visual>
    <collision>
      <origin
        xyz="0 0 0"
        rpy="0 0 0" />
      <geometry>
        <mesh
          filename="package://toy_car/meshes/rear_right_suspension.STL" />
      </geometry>
    </collision>
  </link>
  <joint
    name="rear_right_suspension_joint"
    type="prismatic">
    <origin
      xyz="0 0 -0.06"
      rpy="0 0 0" />
    <parent
      link="rear_right" />
    <child
      link="rear_right_suspension" />
    <axis
      xyz="0 0 -1" />
    <limit
      lower="-0.02"
      upper="0.02"
      effort="1000"
      velocity="1000" />
  </joint>
  <link
    name="camera_left">
    <inertial>
      <origin
        xyz="-0.0120544749097688 -2.64371644598249E-06 0.00129029482254094"
        rpy="0 0 0" />
      <mass
        value="0.0436119950287128" />
      <inertia
        ixx="2.357070580464E-05"
        ixy="-1.01813691700999E-09"
        ixz="2.17579681215313E-08"
        iyy="4.29479133591159E-06"
        iyz="-8.85791113982287E-10"
        izz="2.21058141232449E-05" />
    </inertial>
    <visual>
      <origin
        xyz="0 0 0"
        rpy="0 0 0" />
      <geometry>
        <mesh
          filename="package://toy_car/meshes/cam_left.STL" />
      </geometry>
      <material
        name="">
        <color
          rgba="0.792156862745098 0.819607843137255 0.933333333333333 1" />
      </material>
    </visual>
    <collision>
      <origin
        xyz="0 0 0"
        rpy="0 0 0" />
      <geometry>
        <mesh
          filename="package://toy_car/meshes/cam_left.STL" />
      </geometry>
    </collision>
  </link>
  <joint
    name="camera_left_joint"
    type="fixed">
    <origin
      xyz="0.0245 0.125 0.11"
      rpy="0 0 0" />
    <parent
      link="base_link" />
    <child
      link="camera_left" />
    <axis
      xyz="0 0 0" />
  </joint>
  <link
    name="camera_center">
    <inertial>
      <origin
        xyz="-0.0120544747058804 -2.64441767712509E-06 0.00129029282470135"
        rpy="0 0 0" />
      <mass
        value="0.0436119958195422" />
      <inertia
        ixx="2.3570706297655E-05"
        ixy="-1.01838561350546E-09"
        ixz="2.17586651355488E-08"
        iyy="4.29479058709873E-06"
        iyz="-8.85031082188919E-10"
        izz="2.21058153779503E-05" />
    </inertial>
    <visual>
      <origin
        xyz="0 0 0"
        rpy="0 0 0" />
      <geometry>
        <mesh
          filename="package://toy_car/meshes/cam_center.STL" />
      </geometry>
      <material
        name="">
        <color
          rgba="0.792156862745098 0.819607843137255 0.933333333333333 1" />
      </material>
    </visual>
    <collision>
      <origin
        xyz="0 0 0"
        rpy="0 0 0" />
      <geometry>
        <mesh
          filename="package://toy_car/meshes/cam_center.STL" />
      </geometry>
    </collision>
  </link>
  <joint
    name="camera_center_joint"
    type="fixed">
    <origin
      xyz="0.065337 0 0.1132"
      rpy="0 0.2012 0" />
    <parent
      link="base_link" />
    <child
      link="camera_center" />
    <axis
      xyz="0 0 0" />
  </joint>
  <link
    name="camera_right">
    <inertial>
      <origin
        xyz="-0.0120544749097688 -2.64371644610219E-06 0.00129029482254099"
        rpy="0 0 0" />
      <mass
        value="0.0436119950287128" />
      <inertia
        ixx="2.357070580464E-05"
        ixy="-1.0181369170115E-09"
        ixz="2.17579681215311E-08"
        iyy="4.29479133591163E-06"
        iyz="-8.85791114096477E-10"
        izz="2.21058141232449E-05" />
    </inertial>
    <visual>
      <origin
        xyz="0 0 0"
        rpy="0 0 0" />
      <geometry>
        <mesh
          filename="package://toy_car/meshes/cam_right.STL" />
      </geometry>
      <material
        name="">
        <color
          rgba="0.792156862745098 0.819607843137255 0.933333333333333 1" />
      </material>
    </visual>
    <collision>
      <origin
        xyz="0 0 0"
        rpy="0 0 0" />
      <geometry>
        <mesh
          filename="package://toy_car/meshes/cam_right.STL" />
      </geometry>
    </collision>
  </link>
  <joint
    name="camera_right_joint"
    type="fixed">
    <origin
      xyz="0.0245 -0.125 0.10999737041193"
      rpy="0 0 0" />
    <parent
      link="base_link" />
    <child
      link="camera_right" />
    <axis
      xyz="0 0 0" />
  </joint>
  <link
    name="lidar_top">
    <inertial>
      <origin
        xyz="-0.0120499098018976 0.000527659667923397 -0.0287648857892997"
        rpy="0 0 0" />
      <mass
        value="0.0730845703017379" />
      <inertia
        ixx="1.95808756632736E-05"
        ixy="-1.03933589330764E-07"
        ixz="4.28391188454363E-07"
        iyy="2.41250078188066E-05"
        iyz="-9.42709177675029E-09"
        izz="4.14184514527587E-05" />
    </inertial>
    <visual>
      <origin
        xyz="0 0 0"
        rpy="0 0 0" />
      <geometry>
        <mesh
          filename="package://toy_car/meshes/lidar.STL" />
      </geometry>
      <material
        name="">
        <color
          rgba="0.792156862745098 0.819607843137255 0.933333333333333 1" />
      </material>
    </visual>
    <collision>
      <origin
        xyz="0 0 0"
        rpy="0 0 0" />
      <geometry>
        <mesh
          filename="package://toy_car/meshes/lidar.STL" />
      </geometry>
    </collision>
  </link>
  <joint
    name="lidar_joint"
    type="fixed">
    <origin
      xyz="-0.085232 0 0.177"
      rpy="0 0 0" />
    <parent
      link="base_link" />
    <child
      link="lidar_top" />
    <axis
      xyz="0 0 0" />
  </joint>
  <link
    name="imu">
    <inertial>
      <origin
        xyz="8.67361737988404E-19 -2.77555756156289E-17 -0.00499999999999999"
        rpy="0 0 0" />
      <mass
        value="0.000999999999999999" />
      <inertia
        ixx="1.66666666666666E-08"
        ixy="2.24876659584175E-24"
        ixz="5.51453741702021E-25"
        iyy="1.66666666666666E-08"
        iyz="-3.53318618123475E-25"
        izz="1.66666666666666E-08" />
    </inertial>
    <visual>
      <origin
        xyz="0 0 0"
        rpy="0 0 0" />
      <geometry>
        <mesh
          filename="package://toy_car/meshes/imu.STL" />
      </geometry>
      <material
        name="">
        <color
          rgba="0.792156862745098 0.819607843137255 0.933333333333333 1" />
      </material>
    </visual>
    <collision>
      <origin
        xyz="0 0 0"
        rpy="0 0 0" />
      <geometry>
        <mesh
          filename="package://toy_car/meshes/imu.STL" />
      </geometry>
    </collision>
  </link>
  <joint
    name="imu_joint"
    type="fixed">
    <origin
      xyz="-0.00499999999999977 0 0.13499737041193"
      rpy="0 0 0" />
    <parent
      link="base_link" />
    <child
      link="imu" />
    <axis
      xyz="0 0 0" />
  </joint>
  <link
    name="dummy">
    <inertial>
      <origin
        xyz="8.6736E-19 -2.7756E-17 -0.005"
        rpy="0 0 0" />
      <mass
        value="0.001" />
      <inertia
        ixx="1.6667E-08"
        ixy="2.2488E-24"
        ixz="5.5145E-25"
        iyy="1.6667E-08"
        iyz="-3.5332E-25"
        izz="1.6667E-08" />
    </inertial>
    <visual>
      <origin
        xyz="0 0 0"
        rpy="0 0 0" />
      <geometry>
        <mesh
          filename="package://toy_car/meshes/dummy.STL" />
      </geometry>
      <material
        name="">
        <color
          rgba="0.79216 0.81961 0.93333 1" />
      </material>
    </visual>
    <collision>
      <origin
        xyz="0 0 0"
        rpy="0 0 0" />
      <geometry>
        <mesh
          filename="package://toy_car/meshes/dummy.STL" />
      </geometry>
    </collision>
  </link>
  <joint
    name="dummy_joint"
    type="fixed">
    <origin
      xyz="-0.005 0 0.135"
      rpy="0 0 0" />
    <parent
      link="base_link" />
    <child
      link="dummy" />
    <axis
      xyz="0 0 0" />
  </joint>


  <transmission name="tran_left_wheel">
    <type>transmission_interface/SimpleTransmission</type>
    <joint name="front_left_wheel_joint">
      <hardwareInterface>VelocityJointInterface</hardwareInterface>
    </joint>
    <actuator name="motor1">
      <hardwareInterface>VelocityJointInterface</hardwareInterface>
      <mechanicalReduction>1</mechanicalReduction>
    </actuator>
  </transmission>

  <transmission name="tran_right_wheel">
    <type>transmission_interface/SimpleTransmission</type>
    <joint name="front_right_wheel_joint">
      <hardwareInterface>VelocityJointInterface</hardwareInterface>
    </joint>
    <actuator name="motor2">
      <hardwareInterface>VelocityJointInterface</hardwareInterface>
      <mechanicalReduction>1</mechanicalReduction>
    </actuator>
  </transmission>

  <transmission name="tran_front_left_sus">
    <type>transmission_interface/SimpleTransmission</type>
    <joint name="front_left_suspension_joint">
      <hardwareInterface>hardware_interface/EffortJointInterface</hardwareInterface>
    </joint>
    <actuator name="motor_sus1">
      <hardwareInterface>hardware_interface/EffortJointInterface</hardwareInterface>
      <mechanicalReduction>1</mechanicalReduction>
    </actuator>
  </transmission>

  <transmission name="tran_front_right_sus">
    <type>transmission_interface/SimpleTransmission</type>
    <joint name="front_right_suspension_joint">
      <hardwareInterface>hardware_interface/EffortJointInterface</hardwareInterface>
    </joint>
    <actuator name="motor_sus2">
      <hardwareInterface>hardware_interface/EffortJointInterface</hardwareInterface>
      <mechanicalReduction>1</mechanicalReduction>
    </actuator>
  </transmission>

  <transmission name="tran_rear_left_sus">
    <type>transmission_interface/SimpleTransmission</type>
    <joint name="rear_left_suspension_joint">
      <hardwareInterface>hardware_interface/EffortJointInterface</hardwareInterface>
    </joint>
    <actuator name="motor_sus3">
      <hardwareInterface>hardware_interface/EffortJointInterface</hardwareInterface>
      <mechanicalReduction>1</mechanicalReduction>
    </actuator>
  </transmission>

  <transmission name="tran_rear_right_sus">
    <type>transmission_interface/SimpleTransmission</type>
    <joint name="rear_right_suspension_joint">
      <hardwareInterface>hardware_interface/EffortJointInterface</hardwareInterface>
    </joint>
    <actuator name="motor_sus4">
      <hardwareInterface>hardware_interface/EffortJointInterface</hardwareInterface>
      <mechanicalReduction>1</mechanicalReduction>
    </actuator>
  </transmission>

  <gazebo reference="rear_right_suspension">
    <mu1>0.0001</mu1>
    <mu2>0.0001</mu2>
  </gazebo>

  <gazebo reference="rear_left_suspension">
    <mu1>0.0001</mu1>
    <mu2>0.0001</mu2>
  </gazebo>


  <gazebo reference="front_left_wheel">
    <mu1>1</mu1>
    <mu2>1</mu2>
  </gazebo>

  <gazebo reference="front_left_wheel">
    <mu1>1</mu1>
    <mu2>1</mu2>
  </gazebo>

  <gazebo>
    <plugin name="gazebo_ros_control" filename="libgazebo_ros_control.so">
      <robotNamespace>/toy_car2</robotNamespace>
    </plugin>
  </gazebo>

 <gazebo reference="lidar_top">
    <material>Gazebo/FlatBlack</material>
    <sensor type="ray" name="lds_lfcd_sensor">
      <pose>0 0 0 0 0 0</pose>
      <visualize>false</visualize>
      <update_rate>5</update_rate>
      <ray>
        <scan>
          <horizontal>
            <samples>360</samples>
            <resolution>1</resolution>
            <min_angle>0.0</min_angle>
            <max_angle>6.28319</max_angle>
          </horizontal>
        </scan>
        <range>
          <min>0.120</min>
          <max>3.5</max>
          <resolution>0.015</resolution>
        </range>
        <noise>
          <type>gaussian</type>
          <mean>0.0</mean>
          <stddev>0.01</stddev>
        </noise>
      </ray>
      <plugin name="gazebo_ros_lds_lfcd_controller" filename="libgazebo_ros_laser.so">
        <topicName>scan</topicName>
        <frameName>lidar_top</frameName>
      </plugin>
    </sensor>
  </gazebo>

<gazebo reference="camera_left">
    <sensor type="depth" name="realsense_R200">
      <always_on>true</always_on>
      <visualize>true</visualize>
      <camera>
          <horizontal_fov>1.3439</horizontal_fov>
          <image>
              <width>1920</width>
              <height>1080</height>
              <format>R8G8B8</format>
          </image>
          <depth_camera></depth_camera>
          <clip>
              <near>0.03</near>
              <far>100</far>
          </clip>
      </camera>
      <plugin name="camera_controller" filename="libgazebo_ros_openni_kinect.so">
        <baseline>0.2</baseline>
        <alwaysOn>true</alwaysOn>
        <updateRate>30.0</updateRate>
        <cameraName>camera_left</cameraName>
        <frameName>camera_rgb_optical_frame</frameName>
        <imageTopicName>rgb/image_raw</imageTopicName>
        <depthImageTopicName>depth/image_raw</depthImageTopicName>
        <pointCloudTopicName>depth/points</pointCloudTopicName>
        <cameraInfoTopicName>rgb/camera_info</cameraInfoTopicName>
        <depthImageCameraInfoTopicName>depth/camera_info</depthImageCameraInfoTopicName>
        <pointCloudCutoff>0.4</pointCloudCutoff>
            <hackBaseline>0.07</hackBaseline>
            <distortionK1>0.0</distortionK1>
            <distortionK2>0.0</distortionK2>
            <distortionK3>0.0</distortionK3>
            <distortionT1>0.0</distortionT1>
            <distortionT2>0.0</distortionT2>
        <CxPrime>0.0</CxPrime>
        <Cx>0.0</Cx>
        <Cy>0.0</Cy>
        <focalLength>0</focalLength>
        <hackBaseline>0</hackBaseline>
      </plugin>
    </sensor>
  </gazebo>

<gazebo reference="camera_center">
    <sensor type="depth" name="realsense_R200">
      <always_on>true</always_on>
      <visualize>true</visualize>
      <camera>
          <horizontal_fov>1.3439</horizontal_fov>
          <image>
              <width>1920</width>
              <height>1080</height>
              <format>R8G8B8</format>
          </image>
          <depth_camera></depth_camera>
          <clip>
              <near>0.03</near>
              <far>100</far>
          </clip>
      </camera>
      <plugin name="camera_controller" filename="libgazebo_ros_openni_kinect.so">
        <baseline>0.2</baseline>
        <alwaysOn>true</alwaysOn>
        <updateRate>30.0</updateRate>
        <cameraName>camera_center</cameraName>
        <frameName>camera_rgb_optical_frame</frameName>
        <imageTopicName>rgb/image_raw</imageTopicName>
        <depthImageTopicName>depth/image_raw</depthImageTopicName>
        <pointCloudTopicName>depth/points</pointCloudTopicName>
        <cameraInfoTopicName>rgb/camera_info</cameraInfoTopicName>
        <depthImageCameraInfoTopicName>depth/camera_info</depthImageCameraInfoTopicName>
        <pointCloudCutoff>0.4</pointCloudCutoff>
            <hackBaseline>0.07</hackBaseline>
            <distortionK1>0.0</distortionK1>
            <distortionK2>0.0</distortionK2>
            <distortionK3>0.0</distortionK3>
            <distortionT1>0.0</distortionT1>
            <distortionT2>0.0</distortionT2>
        <CxPrime>0.0</CxPrime>
        <Cx>0.0</Cx>
        <Cy>0.0</Cy>
        <focalLength>0</focalLength>
        <hackBaseline>0</hackBaseline>
      </plugin>
    </sensor>
  </gazebo>

<gazebo reference="camera_right">
    <sensor type="depth" name="realsense_R200">
      <always_on>true</always_on>
      <visualize>true</visualize>
      <camera>
          <horizontal_fov>1.3439</horizontal_fov>
          <image>
              <width>1920</width>
              <height>1080</height>
              <format>R8G8B8</format>
          </image>
          <depth_camera></depth_camera>
          <clip>
              <near>0.03</near>
              <far>100</far>
          </clip>
      </camera>
      <plugin name="camera_controller" filename="libgazebo_ros_openni_kinect.so">
        <baseline>0.2</baseline>
        <alwaysOn>true</alwaysOn>
        <updateRate>30.0</updateRate>
        <cameraName>camera_right</cameraName>
        <frameName>camera_rgb_optical_frame</frameName>
        <imageTopicName>rgb/image_raw</imageTopicName>
        <depthImageTopicName>depth/image_raw</depthImageTopicName>
        <pointCloudTopicName>depth/points</pointCloudTopicName>
        <cameraInfoTopicName>rgb/camera_info</cameraInfoTopicName>
        <depthImageCameraInfoTopicName>depth/camera_info</depthImageCameraInfoTopicName>
        <pointCloudCutoff>0.4</pointCloudCutoff>
            <hackBaseline>0.07</hackBaseline>
            <distortionK1>0.0</distortionK1>
            <distortionK2>0.0</distortionK2>
            <distortionK3>0.0</distortionK3>
            <distortionT1>0.0</distortionT1>
            <distortionT2>0.0</distortionT2>
        <CxPrime>0.0</CxPrime>
        <Cx>0.0</Cx>
        <Cy>0.0</Cy>
        <focalLength>0</focalLength>
        <hackBaseline>0</hackBaseline>
      </plugin>
    </sensor>
  </gazebo>




</robot>
