<?xml version="1.0" encoding="utf-8"?>
<!-- This URDF was automatically created by SolidWorks to URDF Exporter! Originally created by Stephen Brawner (brawner@gmail.com) 
     Commit Version: 1.5.1-0-g916b5db  Build Version: 1.5.7152.31018
     For more information, please see http://wiki.ros.org/sw_urdf_exporter -->
<robot
  name="toy_car">
  <link
    name="base_link">
    <inertial>
      <origin
        xyz="0.10655 0.055281 0.15071"
        rpy="0 0 0" />
      <mass
        value="3.0763" />
      <inertia
        ixx="0.0060335"
        ixy="-1.5803E-06"
        ixz="1.4474E-06"
        iyy="0.0090664"
        iyz="3.2234E-07"
        izz="0.0038925" />
    </inertial>
    <visual>
      <origin
        xyz="0 0 0"
        rpy="0 0 0" />
      <geometry>
        <mesh
          filename="package://toy_car/meshes/base_link.STL" />
      </geometry>
      <material
        name="">
        <color
          rgba="0.79216 0.81961 0.93333 1" />
      </material>
    </visual>
    <collision>
      <origin
        xyz="0 0 0"
        rpy="0 0 0" />
      <geometry>
        <mesh
          filename="package://toy_car/meshes/base_link.STL" />
      </geometry>
    </collision>
  </link>
  <link
    name="front_left_wheel">
    <inertial>
      <origin
        xyz="4.3368E-19 4.3368E-19 0.025"
        rpy="0 0 0" />
      <mass
        value="0.8936" />
      <inertia
        ixx="0.0014378"
        ixy="1.0842E-19"
        ixz="7.7162E-21"
        iyy="0.0014378"
        iyz="8.7955E-21"
        izz="0.002507" />
    </inertial>
    <visual>
      <origin
        xyz="0 0 0"
        rpy="0 0 0" />
      <geometry>
        <mesh
          filename="package://toy_car/meshes/front_left_wheel.STL" />
      </geometry>
      <material
        name="">
        <color
          rgba="1 1 1 1" />
      </material>
    </visual>
    <collision>
      <origin
        xyz="0 0 0"
        rpy="0 0 0" />
      <geometry>
        <mesh
          filename="package://toy_car/meshes/front_left_wheel.STL" />
      </geometry>
    </collision>
  </link>
  <joint
    name="front_left_wheel_joint"
    type="continuous">
    <origin
      xyz="1.2819E-05 -0.3265 -0.003"
      rpy="1.5708 0.86221 0" />
    <parent
      link="base_link" />
    <child
      link="front_left_wheel" />
    <axis
      xyz="0 0 1" />
    <limit effort = "2.3" velocity = "5.23"/>
  </joint>
  <link
    name="front_right_wheel">
    <inertial>
      <origin
        xyz="-2.2226E-18 8.6736E-19 -0.025"
        rpy="0 0 0" />
      <mass
        value="0.8936" />
      <inertia
        ixx="0.0014378"
        ixy="1.3553E-20"
        ixz="4.6175E-20"
        iyy="0.0014378"
        iyz="-1.6767E-21"
        izz="0.002507" />
    </inertial>
    <visual>
      <origin
        xyz="0 0 0"
        rpy="0 0 0" />
      <geometry>
        <mesh
          filename="package://toy_car/meshes/front_right_wheel.STL" />
      </geometry>
      <material
        name="">
        <color
          rgba="1 1 1 1" />
      </material>
    </visual>
    <collision>
      <origin
        xyz="0 0 0"
        rpy="0 0 0" />
      <geometry>
        <mesh
          filename="package://toy_car/meshes/front_right_wheel.STL" />
      </geometry>
    </collision>
  </link>
  <joint
    name="front_right_wheel_joint"
    type="continuous">
    <origin
      xyz="-1.2819E-05 0.0265 -0.003"
      rpy="1.5708 -0.067638 0" />
    <parent
      link="base_link" />
    <child
      link="front_right_wheel" />
    <axis
      xyz="0 0 1" />
    <limit effort = "2.3" velocity = "5.23"/>
  </joint>
  <link
    name="rear_left_caster">
    <inertial>
      <origin
        xyz="-0.0031598 -0.015729 2.498E-16"
        rpy="0 0 0" />
      <mass
        value="0.017712" />
      <inertia
        ixx="3.7169E-06"
        ixy="-3.052E-07"
        ixz="-3.6396E-21"
        iyy="2.8968E-06"
        iyz="-3.1631E-21"
        izz="2.0139E-06" />
    </inertial>
    <visual>
      <origin
        xyz="0 0 0"
        rpy="0 0 0" />
      <geometry>
        <mesh
          filename="package://toy_car/meshes/rear_left_caster.STL" />
      </geometry>
      <material
        name="">
        <color
          rgba="0.89804 0.91765 0.92941 1" />
      </material>
    </visual>
    <collision>
      <origin
        xyz="0 0 0"
        rpy="0 0 0" />
      <geometry>
        <mesh
          filename="package://toy_car/meshes/rear_left_caster.STL" />
      </geometry>
    </collision>
  </link>
  <joint
    name="rear_left_caster_joint"
    type="continuous">
    <origin
      xyz="0.22 -0.26 -0.0225"
      rpy="1.5708 0 3.0462" />
    <parent
      link="base_link" />
    <child
      link="rear_left_caster" />
    <axis
      xyz="0 1 0" />
  </joint>
  <link
    name="rear_left_caster_wheel">
    <inertial>
      <origin
        xyz="0 -2.6021E-18 2.2204E-16"
        rpy="0 0 0" />
      <mass
        value="0.025494" />
      <inertia
        ixx="3.8279E-06"
        ixy="8.065E-23"
        ixz="-1.0588E-21"
        iyy="3.8279E-06"
        iyz="3.2823E-21"
        izz="6.568E-06" />
    </inertial>
    <visual>
      <origin
        xyz="0 0 0"
        rpy="0 0 0" />
      <geometry>
        <mesh
          filename="package://toy_car/meshes/rear_left_caster_wheel.STL" />
      </geometry>
      <material
        name="">
        <color
          rgba="1 1 1 1" />
      </material>
    </visual>
    <collision>
      <origin
        xyz="0 0 0"
        rpy="0 0 0" />
      <geometry>
        <mesh
          filename="package://toy_car/meshes/rear_left_caster_wheel.STL" />
      </geometry>
    </collision>
  </link>
  <joint
    name="rear_left_caster_wheel_joint"
    type="continuous">
    <origin
      xyz="-0.008 -0.033 0"
      rpy="-3.1416 0 -2.9205" />
    <parent
      link="rear_left_caster" />
    <child
      link="rear_left_caster_wheel" />
    <axis
      xyz="0 0 1" />
  </joint>
  <link
    name="rear_right_caster">
    <inertial>
      <origin
        xyz="-0.0031598 -0.015729 -1.7347E-17"
        rpy="0 0 0" />
      <mass
        value="0.017712" />
      <inertia
        ixx="3.7169E-06"
        ixy="-3.052E-07"
        ixz="3.0705E-21"
        iyy="2.8968E-06"
        iyz="-4.5329E-22"
        izz="2.0139E-06" />
    </inertial>
    <visual>
      <origin
        xyz="0 0 0"
        rpy="0 0 0" />
      <geometry>
        <mesh
          filename="package://toy_car/meshes/rear_right_caster.STL" />
      </geometry>
      <material
        name="">
        <color
          rgba="0.89804 0.91765 0.92941 1" />
      </material>
    </visual>
    <collision>
      <origin
        xyz="0 0 0"
        rpy="0 0 0" />
      <geometry>
        <mesh
          filename="package://toy_car/meshes/rear_right_caster.STL" />
      </geometry>
    </collision>
  </link>
  <joint
    name="rear_right_caster_joint"
    type="continuous">
    <origin
      xyz="0.22 -0.04 -0.0225"
      rpy="1.5708 0 3.078" />
    <parent
      link="base_link" />
    <child
      link="rear_right_caster" />
    <axis
      xyz="0 1 0" />
  </joint>
  <link
    name="rear_right_caster_wheel">
    <inertial>
      <origin
        xyz="-5.5511E-17 -2.7756E-17 6.9389E-17"
        rpy="0 0 0" />
      <mass
        value="0.025494" />
      <inertia
        ixx="3.8279E-06"
        ixy="-1.6047E-22"
        ixz="-6.088E-22"
        iyy="3.8279E-06"
        iyz="2.0514E-22"
        izz="6.568E-06" />
    </inertial>
    <visual>
      <origin
        xyz="0 0 0"
        rpy="0 0 0" />
      <geometry>
        <mesh
          filename="package://toy_car/meshes/rear_right_caster_wheel.STL" />
      </geometry>
      <material
        name="">
        <color
          rgba="1 1 1 1" />
      </material>
    </visual>
    <collision>
      <origin
        xyz="0 0 0"
        rpy="0 0 0" />
      <geometry>
        <mesh
          filename="package://toy_car/meshes/rear_right_caster_wheel.STL" />
      </geometry>
    </collision>
  </link>
  <joint
    name="rear_right_caster_wheel_joint"
    type="continuous">
    <origin
      xyz="-0.008 -0.033 0"
      rpy="0 0 -0.38747" />
    <parent
      link="rear_right_caster" />
    <child
      link="rear_right_caster_wheel" />
    <axis
      xyz="0 0 1" />
  </joint>



  <transmission name="tran_left_wheel">
    <type>transmission_interface/SimpleTransmission</type>
    <joint name="front_left_wheel_joint">
      <hardwareInterface>VelocityJointInterface</hardwareInterface>
    </joint>
    <actuator name="motor1">
      <hardwareInterface>VelocityJointInterface</hardwareInterface>
      <mechanicalReduction>1</mechanicalReduction>
    </actuator>
  </transmission>

  <transmission name="tran_right_wheel">
    <type>transmission_interface/SimpleTransmission</type>
    <joint name="front_right_wheel_joint">
      <hardwareInterface>VelocityJointInterface</hardwareInterface>
    </joint>
    <actuator name="motor2">
      <hardwareInterface>VelocityJointInterface</hardwareInterface>
      <mechanicalReduction>1</mechanicalReduction>
    </actuator>
  </transmission>

  <gazebo>
    <plugin name="gazebo_ros_control" filename="libgazebo_ros_control.so">
      <robotNamespace>/toy_car</robotNamespace>
    </plugin>
  </gazebo>

</robot>
