<?xml version="1.0" encoding="utf-8"?>
<!-- This URDF was automatically created by SolidWorks to URDF Exporter! Originally created by Stephen Brawner (brawner@gmail.com) 
     Commit Version:   Build Version: 1.5.7444.6699
     For more information, please see http://wiki.ros.org/sw_urdf_exporter -->
<robot
  name="toy_car">
  <link
    name="base_link">
    <inertial>
      <origin
        xyz="0.084297 -0.15059 0.046491"
        rpy="0 0 0" />
      <mass
        value="3.4415" />
      <inertia
        ixx="0.0094467"
        ixy="-1.3422E-06"
        ixz="-7.1648E-07"
        iyy="0.0043003"
        iyz="-3.3231E-07"
        izz="0.012743" />
    </inertial>
    <visual>
      <origin
        xyz="0 0 0"
        rpy="0 0 0" />
      <geometry>
        <mesh
          filename="package://toy_car/meshes/base_link.STL" />
      </geometry>
      <material
        name="">
        <color
          rgba="0.79216 0.81961 0.93333 1" />
      </material>
    </visual>
    <collision>
      <origin
        xyz="0 0 0"
        rpy="0 0 0" />
      <geometry>
        <mesh
          filename="package://toy_car/meshes/base_link.STL" />
      </geometry>
    </collision>
  </link>
  <link
    name="front_left_wheel">
    <inertial>
      <origin
        xyz="7.3692E-19 4.3368E-19 0.02"
        rpy="0 0 0" />
      <mass
        value="0.389" />
      <inertia
        ixx="0.00072452"
        ixy="-2.0835E-36"
        ixz="8.5856E-21"
        iyy="0.00072452"
        iyz="-6.276E-36"
        izz="0.0013777" />
    </inertial>
    <visual>
      <origin
        xyz="0 0 0"
        rpy="0 0 0" />
      <geometry>
        <mesh
          filename="package://toy_car/meshes/front_left_wheel.STL" />
      </geometry>
      <material
        name="">
        <color
          rgba="1 1 1 1" />
      </material>
    </visual>
    <collision>
      <origin
        xyz="0 0 0"
        rpy="0 0 0" />
      <geometry>
        <mesh
          filename="package://toy_car/meshes/front_left_wheel.STL" />
      </geometry>
    </collision>
  </link>
  <joint
    name="front_left_wheel_joint"
    type="continuous">
    <origin
      xyz="1.2819E-05 -0.3265 -0.003"
      rpy="1.5708 0 0" />
    <parent
      link="base_link" />
    <child
      link="front_left_wheel" />
    <axis
      xyz="0 0 1" />
    <limit
      effort="3.1"
      velocity="7" />
  </joint>
  <link
    name="front_right_wheel">
    <inertial>
      <origin
        xyz="7.5555E-19 0 -0.02"
        rpy="0 0 0" />
      <mass
        value="0.389" />
      <inertia
        ixx="0.00072452"
        ixy="-2.3946E-36"
        ixz="8.5901E-21"
        iyy="0.00072452"
        iyz="-3.2551E-36"
        izz="0.0013777" />
    </inertial>
    <visual>
      <origin
        xyz="0 0 0"
        rpy="0 0 0" />
      <geometry>
        <mesh
          filename="package://toy_car/meshes/front_right_wheel.STL" />
      </geometry>
      <material
        name="">
        <color
          rgba="1 1 1 1" />
      </material>
    </visual>
    <collision>
      <origin
        xyz="0 0 0"
        rpy="0 0 0" />
      <geometry>
        <mesh
          filename="package://toy_car/meshes/front_right_wheel.STL" />
      </geometry>
    </collision>
  </link>
  <joint
    name="front_right_wheel_joint"
    type="continuous">
    <origin
      xyz="-1.2819E-05 0.0265 -0.003"
      rpy="1.5708 0 0" />
    <parent
      link="base_link" />
    <child
      link="front_right_wheel" />
    <axis
      xyz="0 0 1" />
    <limit
      effort="3.1"
      velocity="7" />
  </joint>
  <link
    name="rear_left_caster">
    <inertial>
      <origin
        xyz="0.0031981 -0.014913 -5.5511E-17"
        rpy="0 0 0" />
      <mass
        value="0.0175" />
      <inertia
        ixx="3.687E-06"
        ixy="2.9995E-07"
        ixz="-8.2334E-24"
        iyy="2.8932E-06"
        iyz="6.1441E-22"
        izz="1.983E-06" />
    </inertial>
    <visual>
      <origin
        xyz="0 0 0"
        rpy="0 0 0" />
      <geometry>
        <mesh
          filename="package://toy_car/meshes/rear_left_caster.STL" />
      </geometry>
      <material
        name="">
        <color
          rgba="0.89804 0.91765 0.92941 1" />
      </material>
    </visual>
    <collision>
      <origin
        xyz="0 0 0"
        rpy="0 0 0" />
      <geometry>
        <mesh
          filename="package://toy_car/meshes/rear_left_caster.STL" />
      </geometry>
    </collision>
  </link>
  <joint
    name="rear_left_caster_joint"
    type="continuous">
    <origin
      xyz="0.22 -0.26 -0.0235"
      rpy="1.5708 0 0" />
    <parent
      link="base_link" />
    <child
      link="rear_left_caster" />
    <axis
      xyz="0 1 0" />
    <limit
      lower="0"
      upper="0"
      effort="0"
      velocity="0" />
  </joint>
  <link
    name="rear_left_caster_wheel">
    <inertial>
      <origin
        xyz="0 0 -5.5511E-17"
        rpy="0 0 0" />
      <mass
        value="0.025328" />
      <inertia
        ixx="3.8234E-06"
        ixy="-3.1764E-22"
        ixz="-1.7905E-22"
        iyy="3.8234E-06"
        iyz="2.7501E-22"
        izz="6.5662E-06" />
    </inertial>
    <visual>
      <origin
        xyz="0 0 0"
        rpy="0 0 0" />
      <geometry>
        <mesh
          filename="package://toy_car/meshes/rear_left_caster_wheel.STL" />
      </geometry>
      <material
        name="">
        <color
          rgba="1 1 1 1" />
      </material>
    </visual>
    <collision>
      <origin
        xyz="0 0 0"
        rpy="0 0 0" />
      <geometry>
        <mesh
          filename="package://toy_car/meshes/rear_left_caster_wheel.STL" />
      </geometry>
    </collision>
  </link>
  <joint
    name="rear_left_caster_wheel_joint"
    type="continuous">
    <origin
      xyz="0.008 -0.032 0"
      rpy="0 0 -0.21884" />
    <parent
      link="rear_left_caster" />
    <child
      link="rear_left_caster_wheel" />
    <axis
      xyz="0 0 1" />
  </joint>
  <link
    name="rear_right_caster">
    <inertial>
      <origin
        xyz="0.0031981 -0.014913 6.9389E-18"
        rpy="0 0 0" />
      <mass
        value="0.0175" />
      <inertia
        ixx="3.687E-06"
        ixy="2.9995E-07"
        ixz="2.8933E-22"
        iyy="2.8932E-06"
        iyz="9.8272E-22"
        izz="1.983E-06" />
    </inertial>
    <visual>
      <origin
        xyz="0 0 0"
        rpy="0 0 0" />
      <geometry>
        <mesh
          filename="package://toy_car/meshes/rear_right_caster.STL" />
      </geometry>
      <material
        name="">
        <color
          rgba="0.89804 0.91765 0.92941 1" />
      </material>
    </visual>
    <collision>
      <origin
        xyz="0 0 0"
        rpy="0 0 0" />
      <geometry>
        <mesh
          filename="package://toy_car/meshes/rear_right_caster.STL" />
      </geometry>
    </collision>
  </link>
  <joint
    name="rear_right_caster_joint"
    type="continuous">
    <origin
      xyz="0.22 -0.04 -0.0235"
      rpy="1.5708 0 0" />
    <parent
      link="base_link" />
    <child
      link="rear_right_caster" />
    <axis
      xyz="0 1 0" />
    <limit
      lower="0"
      upper="0"
      effort="0"
      velocity="0" />
  </joint>
  <link
    name="rear_right_caster_wheel">
    <inertial>
      <origin
        xyz="0 0 -6.9389E-18"
        rpy="0 0 0" />
      <mass
        value="0.025328" />
      <inertia
        ixx="3.8234E-06"
        ixy="5.294E-23"
        ixz="-8.7788E-23"
        iyy="3.8234E-06"
        iyz="-5.3208E-25"
        izz="6.5662E-06" />
    </inertial>
    <visual>
      <origin
        xyz="0 0 0"
        rpy="0 0 0" />
      <geometry>
        <mesh
          filename="package://toy_car/meshes/rear_right_caster_wheel.STL" />
      </geometry>
      <material
        name="">
        <color
          rgba="1 1 1 1" />
      </material>
    </visual>
    <collision>
      <origin
        xyz="0 0 0"
        rpy="0 0 0" />
      <geometry>
        <mesh
          filename="package://toy_car/meshes/rear_right_caster_wheel.STL" />
      </geometry>
    </collision>
  </link>
  <joint
    name="rear_right_caster_wheel_joint"
    type="continuous">
    <origin
      xyz="0.008 -0.032 0"
      rpy="3.1416 0 0.10137" />
    <parent
      link="rear_right_caster" />
    <child
      link="rear_right_caster_wheel" />
    <axis
      xyz="0 0 1" />
  </joint>
  <link
    name="camera_left">
    <inertial>
      <origin
        xyz="-0.011554 -2.6437E-06 -0.01271"
        rpy="0 0 0" />
      <mass
        value="0.043612" />
      <inertia
        ixx="2.3571E-05"
        ixy="-1.0181E-09"
        ixz="2.1758E-08"
        iyy="4.2948E-06"
        iyz="-8.8579E-10"
        izz="2.2106E-05" />
    </inertial>
    <visual>
      <origin
        xyz="0 0 0"
        rpy="0 0 0" />
      <geometry>
        <mesh
          filename="package://toy_car/meshes/camera_left.STL" />
      </geometry>
      <material
        name="">
        <color
          rgba="0.79216 0.81961 0.93333 1" />
      </material>
    </visual>
    <collision>
      <origin
        xyz="0 0 0"
        rpy="0 0 0" />
      <geometry>
        <mesh
          filename="package://toy_car/meshes/camera_left.STL" />
      </geometry>
    </collision>
  </link>
  <joint
    name="camera_left_joint"
    type="fixed">
    <origin
      xyz="-0.0375 -0.275 0.134"
      rpy="0 0 -3.1416" />
    <parent
      link="base_link" />
    <child
      link="camera_left" />
    <axis
      xyz="0 0 0" />
  </joint>
  <link
    name="camera_center">
    <inertial>
      <origin
        xyz="-0.011554 -2.6444E-06 -0.01371"
        rpy="0 0 0" />
      <mass
        value="0.043612" />
      <inertia
        ixx="2.3571E-05"
        ixy="-1.0184E-09"
        ixz="2.1759E-08"
        iyy="4.2948E-06"
        iyz="-8.8503E-10"
        izz="2.2106E-05" />
    </inertial>
    <visual>
      <origin
        xyz="0 0 0"
        rpy="0 0 0" />
      <geometry>
        <mesh
          filename="package://toy_car/meshes/camera_center.STL" />
      </geometry>
      <material
        name="">
        <color
          rgba="0.79216 0.81961 0.93333 1" />
      </material>
    </visual>
    <collision>
      <origin
        xyz="0 0 0"
        rpy="0 0 0" />
      <geometry>
        <mesh
          filename="package://toy_car/meshes/camera_center.STL" />
      </geometry>
    </collision>
  </link>
  <joint
    name="camera_center_joint"
    type="fixed">
    <origin
      xyz="-0.072595 -0.15 0.128"
      rpy="0 0.2012 -3.1416" />
    <parent
      link="base_link" />
    <child
      link="camera_center" />
    <axis
      xyz="0 0 0" />
  </joint>
  <link
    name="camera_right">
    <inertial>
      <origin
        xyz="-0.0115544749097688 -2.64371644592698E-06 -0.0127097051774589"
        rpy="0 0 0" />
      <mass
        value="0.0436119950287126" />
      <inertia
        ixx="2.357070580464E-05"
        ixy="-1.01813691696859E-09"
        ixz="2.17579681215314E-08"
        iyy="4.2947913359114E-06"
        iyz="-8.85791113953283E-10"
        izz="2.21058141232447E-05" />
    </inertial>
    <visual>
      <origin
        xyz="0 0 0"
        rpy="0 0 0" />
      <geometry>
        <mesh
          filename="package://toy_car/meshes/camera_right.STL" />
      </geometry>
      <material
        name="">
        <color
          rgba="0.792156862745098 0.819607843137255 0.933333333333333 1" />
      </material>
    </visual>
    <collision>
      <origin
        xyz="0 0 0"
        rpy="0 0 0" />
      <geometry>
        <mesh
          filename="package://toy_car/meshes/camera_right.STL" />
      </geometry>
    </collision>
  </link>
  <joint
    name="camera_right_joint"
    type="fixed">
    <origin
      xyz="-0.0375 -0.025 0.134"
      rpy="0 0 3.1416" />
    <parent
      link="base_link" />
    <child
      link="camera_right" />
    <axis
      xyz="0 0 0" />
  </joint>
  <link
    name="lidar_top">
    <inertial>
      <origin
        xyz="0.01205 -0.00052766 -0.028765"
        rpy="0 0 0" />
      <mass
        value="0.073085" />
      <inertia
        ixx="1.9581E-05"
        ixy="-1.0393E-07"
        ixz="-4.2839E-07"
        iyy="2.4125E-05"
        iyz="9.4271E-09"
        izz="4.1418E-05" />
    </inertial>
    <visual>
      <origin
        xyz="0 0 0"
        rpy="0 0 0" />
      <geometry>
        <mesh
          filename="package://toy_car/meshes/lidar_top.STL" />
      </geometry>
      <material
        name="">
        <color
          rgba="0.79216 0.81961 0.93333 1" />
      </material>
    </visual>
    <collision>
      <origin
        xyz="0 0 0"
        rpy="0 0 0" />
      <geometry>
        <mesh
          filename="package://toy_car/meshes/lidar_top.STL" />
      </geometry>
    </collision>
  </link>
  <joint
    name="lidar_top_joint"
    type="fixed">
    <origin
      xyz="0.081303 -0.15 0.1865"
      rpy="0 0 0" />
    <parent
      link="base_link" />
    <child
      link="lidar_top" />
    <axis
      xyz="0 0 0" />
  </joint>


  <transmission name="tran_left_wheel">
    <type>transmission_interface/SimpleTransmission</type>
    <joint name="front_left_wheel_joint">
      <hardwareInterface>VelocityJointInterface</hardwareInterface>
    </joint>
    <actuator name="motor1">
      <hardwareInterface>VelocityJointInterface</hardwareInterface>
      <mechanicalReduction>1</mechanicalReduction>
    </actuator>
  </transmission>

  <transmission name="tran_right_wheel">
    <type>transmission_interface/SimpleTransmission</type>
    <joint name="front_right_wheel_joint">
      <hardwareInterface>VelocityJointInterface</hardwareInterface>
    </joint>
    <actuator name="motor2">
      <hardwareInterface>VelocityJointInterface</hardwareInterface>
      <mechanicalReduction>1</mechanicalReduction>
    </actuator>
  </transmission>

  <gazebo>
    <plugin name="gazebo_ros_control" filename="libgazebo_ros_control.so">
      <robotNamespace>/toy_car</robotNamespace>
    </plugin>
  </gazebo>

 <gazebo reference="lidar_top">
    <material>Gazebo/FlatBlack</material>
    <sensor type="ray" name="lds_lfcd_sensor">
      <pose>0 0 0 0 0 0</pose>
      <visualize>false</visualize>
      <update_rate>5</update_rate>
      <ray>
        <scan>
          <horizontal>
            <samples>360</samples>
            <resolution>1</resolution>
            <min_angle>0.0</min_angle>
            <max_angle>6.28319</max_angle>
          </horizontal>
        </scan>
        <range>
          <min>0.120</min>
          <max>3.5</max>
          <resolution>0.015</resolution>
        </range>
        <noise>
          <type>gaussian</type>
          <mean>0.0</mean>
          <stddev>0.01</stddev>
        </noise>
      </ray>
      <plugin name="gazebo_ros_lds_lfcd_controller" filename="libgazebo_ros_laser.so">
        <topicName>scan</topicName>
        <frameName>lidar_top</frameName>
      </plugin>
    </sensor>
  </gazebo>

<gazebo reference="camera_left">
    <sensor type="depth" name="realsense_R200">
      <always_on>true</always_on>
      <visualize>true</visualize>
      <camera>
          <horizontal_fov>1.3439</horizontal_fov>
          <image>
              <width>1920</width>
              <height>1080</height>
              <format>R8G8B8</format>
          </image>
          <depth_camera></depth_camera>
          <clip>
              <near>0.03</near>
              <far>100</far>
          </clip>
      </camera>
      <plugin name="camera_controller" filename="libgazebo_ros_openni_kinect.so">
        <baseline>0.2</baseline>
        <alwaysOn>true</alwaysOn>
        <updateRate>30.0</updateRate>
        <cameraName>camera_left</cameraName>
        <frameName>camera_rgb_optical_frame</frameName>
        <imageTopicName>rgb/image_raw</imageTopicName>
        <depthImageTopicName>depth/image_raw</depthImageTopicName>
        <pointCloudTopicName>depth/points</pointCloudTopicName>
        <cameraInfoTopicName>rgb/camera_info</cameraInfoTopicName>
        <depthImageCameraInfoTopicName>depth/camera_info</depthImageCameraInfoTopicName>
        <pointCloudCutoff>0.4</pointCloudCutoff>
            <hackBaseline>0.07</hackBaseline>
            <distortionK1>0.0</distortionK1>
            <distortionK2>0.0</distortionK2>
            <distortionK3>0.0</distortionK3>
            <distortionT1>0.0</distortionT1>
            <distortionT2>0.0</distortionT2>
        <CxPrime>0.0</CxPrime>
        <Cx>0.0</Cx>
        <Cy>0.0</Cy>
        <focalLength>0</focalLength>
        <hackBaseline>0</hackBaseline>
      </plugin>
    </sensor>
  </gazebo>

<gazebo reference="camera_center">
    <sensor type="depth" name="realsense_R200">
      <always_on>true</always_on>
      <visualize>true</visualize>
      <camera>
          <horizontal_fov>1.3439</horizontal_fov>
          <image>
              <width>1920</width>
              <height>1080</height>
              <format>R8G8B8</format>
          </image>
          <depth_camera></depth_camera>
          <clip>
              <near>0.03</near>
              <far>100</far>
          </clip>
      </camera>
      <plugin name="camera_controller" filename="libgazebo_ros_openni_kinect.so">
        <baseline>0.2</baseline>
        <alwaysOn>true</alwaysOn>
        <updateRate>30.0</updateRate>
        <cameraName>camera_center</cameraName>
        <frameName>camera_rgb_optical_frame</frameName>
        <imageTopicName>rgb/image_raw</imageTopicName>
        <depthImageTopicName>depth/image_raw</depthImageTopicName>
        <pointCloudTopicName>depth/points</pointCloudTopicName>
        <cameraInfoTopicName>rgb/camera_info</cameraInfoTopicName>
        <depthImageCameraInfoTopicName>depth/camera_info</depthImageCameraInfoTopicName>
        <pointCloudCutoff>0.4</pointCloudCutoff>
            <hackBaseline>0.07</hackBaseline>
            <distortionK1>0.0</distortionK1>
            <distortionK2>0.0</distortionK2>
            <distortionK3>0.0</distortionK3>
            <distortionT1>0.0</distortionT1>
            <distortionT2>0.0</distortionT2>
        <CxPrime>0.0</CxPrime>
        <Cx>0.0</Cx>
        <Cy>0.0</Cy>
        <focalLength>0</focalLength>
        <hackBaseline>0</hackBaseline>
      </plugin>
    </sensor>
  </gazebo>

<gazebo reference="camera_right">
    <sensor type="depth" name="realsense_R200">
      <always_on>true</always_on>
      <visualize>true</visualize>
      <camera>
          <horizontal_fov>1.3439</horizontal_fov>
          <image>
              <width>1920</width>
              <height>1080</height>
              <format>R8G8B8</format>
          </image>
          <depth_camera></depth_camera>
          <clip>
              <near>0.03</near>
              <far>100</far>
          </clip>
      </camera>
      <plugin name="camera_controller" filename="libgazebo_ros_openni_kinect.so">
        <baseline>0.2</baseline>
        <alwaysOn>true</alwaysOn>
        <updateRate>30.0</updateRate>
        <cameraName>camera_right</cameraName>
        <frameName>camera_rgb_optical_frame</frameName>
        <imageTopicName>rgb/image_raw</imageTopicName>
        <depthImageTopicName>depth/image_raw</depthImageTopicName>
        <pointCloudTopicName>depth/points</pointCloudTopicName>
        <cameraInfoTopicName>rgb/camera_info</cameraInfoTopicName>
        <depthImageCameraInfoTopicName>depth/camera_info</depthImageCameraInfoTopicName>
        <pointCloudCutoff>0.4</pointCloudCutoff>
            <hackBaseline>0.07</hackBaseline>
            <distortionK1>0.0</distortionK1>
            <distortionK2>0.0</distortionK2>
            <distortionK3>0.0</distortionK3>
            <distortionT1>0.0</distortionT1>
            <distortionT2>0.0</distortionT2>
        <CxPrime>0.0</CxPrime>
        <Cx>0.0</Cx>
        <Cy>0.0</Cy>
        <focalLength>0</focalLength>
        <hackBaseline>0</hackBaseline>
      </plugin>
    </sensor>
  </gazebo>


</robot>
